Workbook

Sheet 数据提取表
A1: 发电事业部2024年01月01日电站报表
A2: 序号 | B2: 运行单位 | C2: 项目类型 | D2: 容量（MW） | E2: 天气 | F2: 日辐照量（kWh/m²） | G2: 风速（m/s） | H2: 日标杆机理论发电量（万kWh） | I2: 日实际发电量（万kWh） | J2: 日上网电量（万kWh） | K2: 日限电量（万kWh） | L2: 日限电率（%） | M2: 月累计上网电量（万kWh） | N2: 月计划电量（万kWh） | O2: 月完成率（%） | P2: 月度偏差率（正值为超发，负值为欠发）% | Q2: 年计划上网电量（万kWh） | R2: 年累计上网电量(万kWh） | S2: 年完成率（%） | T2: 发电设备故障损失电量（万kWh） | U2: 发电设备检修损失电量（万kWh） | V2: 输变电设备故障损失电量（万kWh | W2: 输变电设备检修维护损失电量（万kWh） | X2: 电网受累损失电量（万kWh） | Y2: 自然灾害损失电量（万kWh） | Z2: 其他受累损失电量（万kWh） | AA2: 工程期损失电量（万kWh） | AB2: 设备可利用率（日%） | AC2: 检修损失电量（万kWh） | AD2: 故障损失电量（万kWh）
A3: 45292 | B3: 特新光伏电站 | C3: 光伏 | D3: 100 | E3: 多云 | F3: 3.33 | G3: 1.14 | H3: 30.4009 | I3: 30.0999 | J3: 30.0125 | K3: 0 | L3: 0 | M3: 30.0125 | R3: 30.0125 | T3: 0 | U3: 0 | V3: 0 | W3: 0 | X3: 0 | Y3: 0 | Z3: 0 | AA3: 0 | AB3: 1 | AC3: =U3+W3 -> 0 | AD3: =T3+V3 -> 0
A4: 45292 | B4: 华光光伏电站 | C4: 光伏 | D4: 10 | E4: 晴 | F4: 4.31 | G4: 0.39 | H4: 4.347 | I4: 4.028 | J4: 3.96 | K4: 0.319 | L4: 0.0734 | M4: 3.96 | R4: 3.96 | T4: 0 | U4: 0 | V4: 0 | W4: 0 | X4: 0 | Y4: 0 | Z4: 0 | AA4: 0 | AB4: 1 | AC4: =U4+W4 -> 0 | AD4: =T4+V4 -> 0
A5: 45292 | B5: 绿曦光伏电站 | C5: 光伏 | D5: 80 | E5: 晴 | F5: 3 | G5: 0.71 | H5: 21.52 | I5: 20.58 | J5: 20.35 | K5: 0 | L5: 0 | M5: 20.35 | R5: 20.35 | T5: 0 | U5: 0 | V5: 0 | W5: 0 | X5: 0 | Y5: 0 | Z5: 0 | AA5: 0 | AB5: 1 | AC5: =U5+W5 -> 0 | AD5: =T5+V5 -> 0
A6: 45292 | B6: 光羿青阳光伏电站 | C6: 光伏 | D6: 100 | E6: 晴 | F6: 3.62 | G6: 0 | H6: 30.0269 | I6: 28.0798 | J6: 27.058 | K6: 1.8528 | L6: 0.0619 | M6: 27.058 | R6: 27.058 | T6: 0.0656 | U6: 0 | V6: 0 | W6: 0 | X6: 0 | Y6: 0.0287 | Z6: 0 | AA6: 0 | AB6: 0.9978 | AC6: =U6+W6 -> 0 | AD6: =T6+V6 -> 0.0656
A7: 45292 | B7: 行唐郜河光伏电站 | C7: 光伏 | D7: 5.48 | E7: 阴 | F7: 2.12 | G7: 0 | H7: 1.0221 | I7: 1.0221 | J7: 0.532 | K7: 0 | L7: 0 | M7: 0.532 | R7: 0.532 | T7: 0 | U7: 0 | V7: 0 | W7: 0 | X7: 0 | Y7: 0 | Z7: 0 | AA7: 0 | AB7: 1 | AC7: =U7+W7 -> 0 | AD7: =T7+V7 -> 0
A8: 45292 | B8: 奈曼旗汇特光伏电站 | C8: 光伏 | D8: 30 | E8: 多云 | F8: 2.87 | G8: 0 | H8: 1.7407 | I8: 1.7407 | J8: 1.6368 | K8: 0 | L8: 0 | M8: 1.6368 | R8: 1.6368 | T8: 0 | U8: 0 | V8: 0 | W8: 0 | X8: 0 | Y8: 0 | Z8: 0 | AA8: 0 | AB8: 1 | AC8: =U8+W8 -> 0 | AD8: =T8+V8 -> 0
A9: 45292 | B9: 特能星光#3光伏电站 | C9: 光伏 | D9: 20 | E9: 多云 | F9: 5.18 | G9: 1.7 | H9: 11.6607 | I9: 10.99 | J9: 10.9732 | K9: 0 | L9: 0 | M9: 10.9732 | R9: 10.9732 | T9: 0 | U9: 0 | V9: 0 | W9: 0 | X9: 0 | Y9: 0 | Z9: 0 | AA9: 0 | AB9: 1 | AC9: =U9+W9 -> 0 | AD9: =T9+V9 -> 0
A10: 45292 | B10: 干龙潭光伏电站 | C10: 光伏 | D10: 30 | E10: 多云 | F10: 3.51 | G10: 0.8 | H10: 8.7329 | I10: 8.6122 | J10: 8.4053 | K10: 0 | L10: 0 | M10: 8.4053 | R10: 8.4053 | T10: 4.8662 | U10: 0 | V10: 0 | W10: 0 | X10: 0 | Y10: 0 | Z10: 0 | AA10: 0 | AB10: 1 | AC10: =U10+W10 -> 0 | AD10: =T10+V10 -> 4.8662
A11: 45292 | B11: 光炽将军尧储能电站 | C11: 光伏 | D11: 300 | E11: 晴天 | F11: 3.17 | G11: 0 | H11: 129.024 | I11: 122.2894 | J11: 107.25 | K11: 6.7347 | L11: 0.0522 | M11: 107.25 | R11: 107.25 | T11: 0 | U11: 0 | V11: 0 | W11: 0 | X11: 0 | Y11: 0 | Z11: 0 | AA11: 0 | AB11: 1 | AC11: =U11+W11 -> 0 | AD11: =T11+V11 -> 0
A12: 45292 | B12: 110kV晖源光伏电站 | C12: 光伏 | D12: 50 | E12: 晴 | F12: 2.21 | G12: 1.22 | H12: 9.45 | I12: 9.324 | J12: 9.24 | K12: 0 | L12: 0 | M12: 9.24 | R12: 9.24 | T12: 0.0223 | U12: 0 | V12: 0 | W12: 0 | X12: 0 | Y12: 0 | Z12: 0 | AA12: 0 | AB12: 0.9977 | AC12: =U12+W12 -> 0 | AD12: =T12+V12 -> 0.0223
A13: 45292 | B13: 子牙关光伏电站 | C13: 光伏 | D13: 30 | E13: 晴 | F13: 5.24 | G13: 0.61 | H13: 13.0519 | I13: 12.796 | J13: 12.768 | K13: 0 | L13: 0 | M13: 12.768 | R13: 12.768 | T13: 0 | U13: 0 | V13: 0 | W13: 0 | X13: 0 | Y13: 0 | Z13: 0 | AA13: 0 | AB13: 1 | AC13: =U13+W13 -> 0 | AD13: =T13+V13 -> 0
A14: 45292 | B14: 武晟庄华光伏电站 | C14: 光伏 | D14: 130 | E14: 晴转多云 | F14: 5.04 | G14: 0.83 | H14: 69.481 | I14: 54.1392 | J14: 53.5241 | K14: 15.34 | L14: 0.2208 | M14: 53.5241 | R14: 53.5241 | T14: 0 | U14: 0 | V14: 0 | W14: 0 | X14: 0 | Y14: 0 | Z14: 0 | AA14: 0 | AB14: 1 | AC14: =U14+W14 -> 0 | AD14: =T14+V14 -> 0
... A39: 45292 | B39: 君盛托里风电一场 | C39: 风机 | D39: 100 | E39: 晴 | F39: 0 | G39: 3.59 | H39: 18.5596 | I39: 18.5596 | J39: 17.5098 | K39: 0 | L39: 0 | M39: 17.5098 | R39: 17.5098 | T39: 0 | U39: 0 | V39: 0 | W39: 0 | X39: 0 | Y39: 0 | Z39: 0 | AA39: 0 | AB39: 0.8379 | AC39: =U39+W39 -> 0 | AD39: =T39+V39 -> 0
A40: 45292 | B40: 100MW星奥光伏电站 | C40: 光伏 | D40: 100 | E40: 多云 | F40: 5.18 | G40: / | H40: 53.872 | I40: 8.59 | J40: 8.246 | K40: 0 | L40: 0.8405 | M40: 8.246 | N40: 1007 | O40: 0.0082 | P40: -0.024 | Q40: / | R40: 8.246 | S40: / | T40: 0 | U40: 0 | V40: 0 | W40: 0 | X40: 0 | Y40: 0 | Z40: 0 | AA40: 0 | AB40: 1 | AC40: =U40+W40 -> 0 | AD40: =T40+V40 -> 0
A41: 45292 | B41: 军红风电场 | C41: 风电 | D41: 100 | E41: 晴 | F41: / | G41: 1.4 | H41: 0.9915 | I41: 0.84 | J41: 0.6776 | K41: 0 | L41: 0 | M41: 0.6776 | N41: 127 | O41: 0.0053 | P41: -0.0267 | Q41: / | R41: 0.6776 | S41: / | T41: 0 | U41: 0 | V41: 0 | W41: 0 | X41: 0 | Y41: 0 | Z41: 0 | AA41: 0 | AB41: 1 | AC41: =U41+W41 -> 0 | AD41: =T41+V41 -> 0
A42: 45292 | B42: 天津武清白古屯风电场 | C42: 风电 | D42: 33 | E42: 晴 | F42: / | G42: 4.63 | H42: 1.9784 | I42: 1.8047 | J42: 1.666 | K42: 0 | L42: 0 | M42: 1.666 | N42: / | O42: / | P42: / | Q42: / | R42: 1.666 | S42: / | T42: 0 | U42: 0 | V42: 0 | W42: 0 | X42: 0 | Y42: 0 | Z42: 0 | AA42: 0 | AB42: 1 | AC42: =U42+W42 -> 0 | AD42: =T42+V42 -> 0
A43: 45292 | B43: 佳阳光储电站 | C43: 光储 | D43: 49.8 | E43: 晴 | F43: 4.64 | G43: 6.81 | H43: 23.072 | I43: 22.9572 | J43: 23.76 | K43: 0 | L43: 0 | M43: 23.76 | N43: / | O43: / | P43: / | Q43: / | R43: 23.76 | S43: / | T43: 0 | U43: 0 | V43: 0 | W43: 0 | X43: 0 | Y43: 0 | Z43: 0 | AA43: 0 | AB43: 1 | AC43: =U43+W43 -> 0 | AD43: =T43+V43 -> 0
A44: 45292 | B44: 110kV昙泉光伏电站 | C44: 光伏 | D44: 100 | E44: 阴 | F44: 10.473 | G44: 2.19 | H44: 0 | I44: 3.41 | J44: 3.0261 | K44: 0 | L44: 0 | M44: 3.0261 | N44: 0 | O44: 0 | P44: 0 | Q44: 0 | R44: 3.0261 | S44: 0 | T44: 0 | U44: 0 | V44: 0 | W44: 0 | X44: 0 | Y44: 0 | Z44: 0 | AA44: 0 | AB44: 1 | AC44: =U44+W44 -> 0 | AD44: =T44+V44 -> 0
A45: 45292 | B45: 干龙潭光伏电站二期 | C45: 光储 | D45: 50 | E45: 多云 | F45: 2.57 | G45: 0.92 | H45: 9.6567 | I45: 9.4067 | J45: 9.3267 | K45: 0 | L45: 0 | M45: 9.3267 | N45: 653 | O45: 0.0143 | Q45: 6458 | R45: 9.3267 | S45: 0.0014 | T45: 0 | U45: 0 | V45: 0 | W45: 0 | X45: 0 | Y45: 0 | Z45: 0 | AA45: 0 | AB45: 1 | AC45: =U45+W45 -> 0 | AD45: =T45+V45 -> 0
A46: 发电事业部2024年01月02日电站报表
A47: 序号 | B47: 运行单位 | C47: 项目类型 | D47: 容量（MW） | E47: 天气 | F47: 日辐照量（kWh/m²） | G47: 风速（m/s） | H47: 日标杆机理论发电量（万kWh） | I47: 日实际发电量（万kWh） | J47: 日上网电量（万kWh） | K47: 日限电量（万kWh） | L47: 日限电率（%） | M47: 月累计上网电量（万kWh） | N47: 月计划电量（万kWh） | O47: 月完成率（%） | P47: 月度偏差率（正值为超发，负值为欠发）% | Q47: 年计划上网电量（万kWh） | R47: 年累计上网电量(万kWh） | S47: 年完成率（%） | T47: 发电设备故障损失电量（万kWh） | U47: 发电设备检修损失电量（万kWh） | V47: 输变电设备故障损失电量（万kWh | W47: 输变电设备检修维护损失电量（万kWh） | X47: 电网受累损失电量（万kWh） | Y47: 自然灾害损失电量（万kWh） | Z47: 其他受累损失电量（万kWh） | AA47: 工程期损失电量（万kWh） | AB47: 设备可利用率（日%） | AC47: 检修损失电量（万kWh） | AD47: 故障损失电量（万kWh）
A48: 45293 | B48: 特新光伏电站 | C48: 光伏 | D48: 100 | E48: 多云 | F48: 3.71 | G48: 1.8 | H48: 32.6875 | I48: 26.775 | J48: 26.6875 | K48: 6 | L48: 0.1831 | M48: 56.7 | R48: 56.7 | T48: 0 | U48: 0 | V48: 0 | W48: 0 | X48: 0 | Y48: 0 | Z48: 0 | AA48: 0 | AB48: 1 | AC48: =U48+W48 -> 0 | AD48: =T48+V48 -> 0
A49: 45293 | B49: 奈曼旗汇特光伏电站 | C49: 光伏 | D49: 30 | E49: 晴 | F49: 5.51 | G49: 0 | H49: 11.6239 | I49: 11.6239 | J49: 11.5632 | K49: 0 | L49: 0 | M49: 13.2 | R49: 13.2 | T49: 0 | U49: 0 | V49: 0 | W49: 0 | X49: 0 | Y49: 0 | Z49: 0 | AA49: 0 | AB49: 1 | AC49: =U49+W49 -> 0 | AD49: =T49+V49 -> 0
A50: 45293 | B50: 华光光伏电站 | C50: 光伏 | D50: 10 | E50: 晴 | F50: 4.34 | G50: 1.21 | H50: 4.0464 | I50: 2.7076 | J50: 2.64 | K50: 0 | L50: 0 | M50: 6.6 | R50: 6.6 | T50: 0 | U50: 0 | V50: 0 | W50: 0 | X50: 0 | Y50: 0 | Z50: 0 | AA50: 0 | AB50: 1 | AC50: =U50+W50 -> 0 | AD50: =T50+V50 -> 0
A51: 45293 | B51: 特能星光#3光伏电站 | C51: 光伏 | D51: 20 | E51: 晴 | F51: 5.34 | G51: 4 | H51: 10.9685 | I51: 10.4681 | J51: 10.4524 | K51: 0.5005 | L51: 0.0456 | M51: 21.4256 | R51: 21.4256 | T51: 0 | U51: 0 | V51: 0 | W51: 0 | X51: 0 | Y51: 0 | Z51: 0 | AA51: 0 | AB51: 1 | AC51: =U51+W51 -> 0 | AD51: =T51+V51 -> 0
A52: 45293 | B52: 行唐郜河光伏电站 | C52: 光伏 | D52: 5.48 | E52: 阴 | F52: 2.51 | G52: 0 | H52: 1.2605 | I52: 1.2605 | J52: 1.064 | K52: 0 | L52: 0 | M52: 1.596 | R52: 1.596 | T52: 0 | U52: 0 | V52: 0 | W52: 0 | X52: 0 | Y52: 0 | Z52: 0 | AA52: 0 | AB52: 1 | AC52: =U52+W52 -> 0 | AD52: =T52+V52 -> 0
A53: 45293 | B53: 110kV晖源光伏电站 | C53: 光伏 | D53: 50 | E53: 多云 | F53: 5.63 | G53: 2.38 | H53: 23.976 | I53: 23.856 | J53: 23.76 | K53: 0 | L53: 0 | M53: 33 | R53: 33 | T53: 0.0491 | U53: 0 | V53: 0 | W53: 0 | X53: 0 | Y53: 0 | Z53: 0 | AA53: 0 | AB53: 0.9978 | AC53: =U53+W53 -> 0 | AD53: =T53+V53 -> 0.0491
A54: 45293 | B54: 光羿青阳光伏电站 | C54: 光伏 | D54: 100 | E54: 晴 | F54: 5.32 | G54: 0 | H54: 43.2488 | I54: 37.6727 | J54: 36.388 | K54: 5.4783 | L54: 0.127 | M54: 63.446 | R54: 63.446 | T54: 0.068 | U54: 0 | V54: 0 | W54: 0 | X54: 0 | Y54: 0.0298 | Z54: 0 | AA54: 0 | AB54: 0.9984 | AC54: =U54+W54 -> 0 | AD54: =T54+V54 -> 0.068
A55: 45293 | B55: 绿曦光伏电站 | C55: 光伏 | D55: 80 | E55: 晴 | F55: 5.34 | G55: 1.84 | H55: 37.08 | I55: 36.4 | J55: 36.3 | K55: 0 | L55: 0 | M55: 56.65 | R55: 56.65 | T55: 0 | U55: 0 | V55: 0 | W55: 0 | X55: 0 | Y55: 0 | Z55: 0 | AA55: 0 | AB55: 1 | AC55: =U55+W55 -> 0 | AD55: =T55+V55 -> 0
A56: 45293 | B56: 光炽将军尧储能电站 | C56: 光伏 | D56: 300 | E56: 晴天 | F56: 4.16 | G56: 0 | H56: 160.6749 | I56: 112.6515 | J56: 112.299 | K56: 48.0234 | L56: 0.2989 | M56: 219.549 | R56: 219.549 | T56: 0 | U56: 0 | V56: 0 | W56: 0 | X56: 0 | Y56: 0 | Z56: 0 | AA56: 0 | AB56: 1 | AC56: =U56+W56 -> 0 | AD56: =T56+V56 -> 0
A57: 45293 | B57: 干龙潭光伏电站 | C57: 光伏 | D57: 30 | E57: 多云 | F57: 4.2 | G57: 0.8 | H57: 10.2478 | I57: 10.0425 | J57: 9.9031 | K57: 0 | L57: 0 | M57: 18.3084 | R57: 18.3084 | T57: 3.1457 | U57: 0 | V57: 0 | W57: 0 | X57: 0 | Y57: 0 | Z57: 0 | AA57: 0 | AB57: 1 | AC57: =U57+W57 -> 0 | AD57: =T57+V57 -> 3.1457
A58: 45293 | B58: 子牙关光伏电站 | C58: 光伏 | D58: 30 | E58: 晴 | F58: 5.71 | G58: 0.71 | H58: 14.1943 | I58: 13.916 | J58: 13.888 | K58: 0 | L58: 0 | M58: 26.656 | R58: 26.656 | T58: 0 | U58: 0 | V58: 0 | W58: 0 | X58: 0 | Y58: 0 | Z58: 0 | AA58: 0 | AB58: 1 | AC58: =U58+W58 -> 0 | AD58: =T58+V58 -> 0
A59: 45293 | B59: 武晟庄华光伏电站 | C59: 光伏 | D59: 130 | E59: 晴 | F59: 5.35 | G59: 0.11 | H59: 70.2166 | I59: 54.7024 | J59: 53.6914 | K59: 15.51 | L59: 0.2209 | M59: 107.2155 | R59: 107.2155 | T59: 0 | U59: 0 | V59: 0 | W59: 0 | X59: 0 | Y59: 0 | Z59: 0 | AA59: 0 | AB59: 1 | AC59: =U59+W59 -> 0 | AD59: =T59+V59 -> 0
... A84: 45293 | B84: 特变思甜东风电一场 | C84: 风机 | D84: 200 | E84: 阴 | F84: 0 | G84: 4.36 | H84: 59.5702 | I84: 59.5702 | J84: 58.08 | K84: 0 | L84: 0 | M84: 81.18 | R84: 81.18 | T84: 0 | U84: 0 | V84: 0 | W84: 0 | X84: 0 | Y84: 0 | Z84: 0 | AA84: 0 | AB84: 0.9989 | AC84: =U84+W84 -> 0 | AD84: =T84+V84 -> 0
A85: 45293 | B85: 100MW星奥光伏电站 | C85: 光伏 | D85: 100 | E85: 晴 | F85: 5.34 | G85: / | H85: 53.3611 | I85: 9.1618 | J85: 8.414 | K85: 0 | L85: 0.8283 | M85: 16.66 | N85: 1007 | O85: 0.0165 | P85: -0.048 | Q85: / | R85: 16.66 | S85: / | T85: 0 | U85: 0 | V85: 0 | W85: 0 | X85: 0 | Y85: 0 | Z85: 0 | AA85: 0 | AB85: 1 | AC85: =U85+W85 -> 0 | AD85: =T85+V85 -> 0
A86: 45293 | B86: 军红风电场 | C86: 风电 | D86: 100 | E86: 晴 | F86: / | G86: 3.44 | H86: 1.88 | I86: 1.68 | J86: 1.496 | K86: 0 | L86: 0 | M86: 2.1736 | N86: 127 | O86: 0.0171 | P86: -0.0201 | Q86: / | R86: 2.1736 | S86: / | T86: 0 | U86: 0 | V86: 0 | W86: 0 | X86: 0 | Y86: 0 | Z86: 0 | AA86: 0 | AB86: 1 | AC86: =U86+W86 -> 0 | AD86: =T86+V86 -> 0
A87: 45293 | B87: 天津武清白古屯风电场 | C87: 风电 | D87: 33 | E87: 晴 | F87: / | G87: 4.88 | H87: 1.9941 | I87: 1.5208 | J87: 1.412 | K87: 0 | L87: 0 | M87: 3.078 | N87: / | O87: / | P87: / | Q87: / | R87: 3.078 | S87: / | T87: 0 | U87: 0 | V87: 0 | W87: 0 | X87: 0 | Y87: 0 | Z87: 0 | AA87: 0.4733 | AB87: 1 | AC87: =U87+W87 -> 0 | AD87: =T87+V87 -> 0
A88: 45293 | B88: 佳阳光储电站 | C88: 光储 | D88: 51 | E88: 小雨 | F88: 0.38 | G88: / | H88: 6.24 | I88: 6.2118 | J88: 5.28 | K88: 0 | L88: 0 | M88: 29.04 | N88: 174 | O88: 0.1668 | Q88: / | R88: 29.04 | T88: 0 | U88: 0 | V88: 0 | W88: 0 | X88: 0 | Y88: 0 | Z88: 0 | AA88: 0 | AB88: 1 | AC88: =U88+W88 -> 0 | AD88: =T88+V88 -> 0
...

Sheet 日报
B3: 选择日期 | D3: 45414
B4: 发电运营事业部5月2日BOO电站电量数据报表 | AG4: 季度累计
B5: 序号 | C5: 电站名称 | D5: 容量（MW） | E5: 天气 | F5: 日辐照量（kWh/m2）风速（m/s） | G5: 日标杆机理论发电量（万kWh） | H5: 日实际发电量（万kWh） | I5: 日上网电量（万kWh） | J5: 日限电量 （万kWh） | K5: 日限电率（%） | L5: 月累计电量（万kWh） | M5: 月计划电量（万kWh） | N5: 月度偏差电量（万kWh） | O5: 月完成率（%） | P5: 月度偏差率（%） | Q5: 季度累计电量（万kWh） | R5: 季度计划电量（万kWh） | S5: 季度偏差电量（万kWh） | T5: 季度完成率（%） | U5: 季度偏差率（%） | V5: 年累计上网电量（万kWh） | W5: 年计划上网电量（万kWh） | X5: 年度偏差电量（万kWh） | Y5: 年完成率（%） | Z5: 年度偏差率（%） | AA5: 检修损失电量（万kWh） | AB5: 故障损失电量（万kWh） | AC5: 备注（TOP3偏差原因） | AG5: 4月 | AH5: 5月
A6: 特新光伏电站 | B6: BO01 | C6: 阳泉特新 | D6: 100 | E6: =LOOKUP(1,0/(($D$3=数据提取表!$A:$A)*($A6=数据提取表!$B:$B)),数据提取表!E:E) -> 晴 | F6: =LOOKUP(1,0/(($D$3=数据提取表!$A:$A)*($A6=数据提取表!$B:$B)),数据提取表!F:F) -> 6.54 | G6: =LOOKUP(1,0/(($D$3=数据提取表!$A:$A)*($A6=数据提取表!$B:$B)),数据提取表!H:H) -> 63.0998 | H6: =LOOKUP(1,0/(($D$3=数据提取表!$A:$A)*($A6=数据提取表!$B:$B)),数据提取表!I:I) -> 62.475 | I6: =LOOKUP(1,0/(($D$3=数据提取表!$A:$A)*($A6=数据提取表!$B:$B)),数据提取表!J:J) -> 62.3 | J6: =LOOKUP(1,0/(($D$3=数据提取表!$A:$A)*($A6=数据提取表!$B:$B)),数据提取表!K:K) -> 0 | K6: =J6/G6 -> 0 | L6: =LOOKUP(1,0/(($D$3=数据提取表!$A:$A)*($A6=数据提取表!$B:$B)),数据提取表!M:M) -> 117.6 | M6: =计划电量!O3 -> 1501 | N6: =L6-M6/31*日报辅助图!$D$1 -> 20.76129 | O6: =L6/M6 -> 0.078347768 | P6: =N6/M6 -> 0.013831639 | Q6: =L6+AG6+AH6 -> 1401.575 | R6: =计划电量!H3 -> 4357.4 | S6: =Q6-(计划电量!N3+计划电量!O3/31*日报辅助图!$D$1) -> 0.33629032 | T6: =Q6/R6 -> 0.32165397 | U6: =S6/R6 -> 7.7176831e-05 | V6: {=LOOKUP(1,0/(($D$3=数据提取表!$A:$A)*($A6=数据提取表!$B:$B)),数据提取表!R:R)} -> 4740.6625 | W6: =计划电量!F3 -> 14972.4 | X6: =V6-(计划电量!G3+计划电量!N3+计划电量!O3/31*日报辅助图!$D$1) -> -219.57621 | Y6: =V6/W6 -> 0.31662676 | Z6: =X6/W6 -> -0.014665398 | AA6: {=LOOKUP(1,0/(($D$3=数据提取表!$A:$A)*($A6=数据提取表!$B:$B)),数据提取表!AC:AC)} -> 0 | AB6: {=LOOKUP(1,0/(($D$3=数据提取表!$A:$A)*($A6=数据提取表!$B:$B)),数据提取表!AD:AD)} -> 0 | AC6: TOP1:景峡思甜东：月度负偏差220.47万kWh，偏差率-4.98%，主要为风资源未达预期。 TOP2:中闽大石头：月度负偏差184.66万kWh，偏差率-3.15%，主要为风资源未达预期。 TOP3:嘉裕大石头：月度负偏差144.81万kWh，偏差率-4.02%，主要为沙尘暴天气42台(11台故障长停)烟雾传感器动作风机环网柜跳闸导致受累损失80万kWh。 | AG6: 1283.975
A7: 110kV晖源光伏电站 | B7: BO02 | C7: 芮城晖源 | D7: 50 | E7: =LOOKUP(1,0/(($D$3=数据提取表!$A:$A)*($A7=数据提取表!$B:$B)),数据提取表!E:E) -> 晴 | F7: =LOOKUP(1,0/(($D$3=数据提取表!$A:$A)*($A7=数据提取表!$B:$B)),数据提取表!F:F) -> 7.51 | G7: =LOOKUP(1,0/(($D$3=数据提取表!$A:$A)*($A7=数据提取表!$B:$B)),数据提取表!H:H) -> 31.9854 | H7: =LOOKUP(1,0/(($D$3=数据提取表!$A:$A)*($A7=数据提取表!$B:$B)),数据提取表!I:I) -> 30.45 | I7: =LOOKUP(1,0/(($D$3=数据提取表!$A:$A)*($A7=数据提取表!$B:$B)),数据提取表!J:J) -> 30.36 | J7: =LOOKUP(1,0/(($D$3=数据提取表!$A:$A)*($A7=数据提取表!$B:$B)),数据提取表!K:K) -> 0.5354 | K7: =J7/G7 -> 0.016738887 | L7: =LOOKUP(1,0/(($D$3=数据提取表!$A:$A)*($A7=数据提取表!$B:$B)),数据提取表!M:M) -> 63.36 | M7: =计划电量!O4 -> 601 | N7: =L7-M7/31*日报辅助图!$D$1 -> 24.585806 | O7: =L7/M7 -> 0.10542429 | P7: =N7/M7 -> 0.040908164 | Q7: =L7+AG7+AH7 -> 698.28 | R7: =计划电量!H4 -> 1964 | S7: =Q7-(计划电量!N4+计划电量!O4/31*日报辅助图!$D$1) -> 56.505806 | T7: =Q7/R7 -> 0.35553971 | U7: =S7/R7 -> 0.028770777 | V7: {=LOOKUP(1,0/(($D$3=数据提取表!$A:$A)*($A7=数据提取表!$B:$B)),数据提取表!R:R)} -> 2123.44 | W7: =计划电量!F4 -> 7203 | X7: =V7-(计划电量!G4+计划电量!N4+计划电量!O4/31*日报辅助图!$D$1) -> -235.33419 | Y7: =V7/W7 -> 0.29479939 | Z7: =X7/W7 -> -0.032671691 | AA7: {=LOOKUP(1,0/(($D$3=数据提取表!$A:$A)*($A7=数据提取表!$B:$B)),数据提取表!AC:AC)} -> 0 | AB7: {=LOOKUP(1,0/(($D$3=数据提取表!$A:$A)*($A7=数据提取表!$B:$B)),数据提取表!AD:AD)} -> 0 | AG7: 634.92
A8: 四槐光华光伏电站 | B8: BO03 | C8: 新泰四槐 | D8: 50 | E8: =LOOKUP(1,0/(($D$3=数据提取表!$A:$A)*($A8=数据提取表!$B:$B)),数据提取表!E:E) -> 晴 | F8: =LOOKUP(1,0/(($D$3=数据提取表!$A:$A)*($A8=数据提取表!$B:$B)),数据提取表!F:F) -> 7.51 | G8: =LOOKUP(1,0/(($D$3=数据提取表!$A:$A)*($A8=数据提取表!$B:$B)),数据提取表!H:H) -> 32.0852 | H8: =LOOKUP(1,0/(($D$3=数据提取表!$A:$A)*($A8=数据提取表!$B:$B)),数据提取表!I:I) -> 17.045 | I8: =LOOKUP(1,0/(($D$3=数据提取表!$A:$A)*($A8=数据提取表!$B:$B)),数据提取表!J:J) -> 16.94 | J8: =LOOKUP(1,0/(($D$3=数据提取表!$A:$A)*($A8=数据提取表!$B:$B)),数据提取表!K:K) -> 15.0402 | K8: =J8/G8 -> 0.46875818 | L8: =LOOKUP(1,0/(($D$3=数据提取表!$A:$A)*($A8=数据提取表!$B:$B)),数据提取表!M:M) -> 30.66 | M8: =计划电量!O5 -> 656 | N8: =L8-M8/31*日报辅助图!$D$1 -> -11.662581 | O8: =L8/M8 -> 0.046737805 | P8: =N8/M8 -> -0.017778324 | Q8: =L8+AG8+AH8 -> 672 | R8: =计划电量!H5 -> 1954 | S8: =Q8-(计划电量!N5+计划电量!O5/31*日报辅助图!$D$1) -> 27.677419 | T8: =Q8/R8 -> 0.34390993 | U8: =S8/R8 -> 0.014164493 | V8: {=LOOKUP(1,0/(($D$3=数据提取表!$A:$A)*($A8=数据提取表!$B:$B)),数据提取表!R:R)} -> 1799.49 | W8: =计划电量!F5 -> 6762 | X8: =V8-(计划电量!G5+计划电量!N5+计划电量!O5/31*日报辅助图!$D$1) -> -420.83258 | Y8: =V8/W8 -> 0.26611801 | Z8: =X8/W8 -> -0.062234928 | AA8: {=LOOKUP(1,0/(($D$3=数据提取表!$A:$A)*($A8=数据提取表!$B:$B)),数据提取表!AC:AC)} -> 0 | AB8: {=LOOKUP(1,0/(($D$3=数据提取表!$A:$A)*($A8=数据提取表!$B:$B)),数据提取表!AD:AD)} -> 0 | AG8: 641.34
A9: 华风风电场 | B9: BO04 | C9: 崇仁华风 | D9: 50 | E9: =LOOKUP(1,0/(($D$3=数据提取表!$A:$A)*($A9=数据提取表!$B:$B)),数据提取表!E:E) -> 小雨 | F9: =LOOKUP(1,0/(($D$3=数据提取表!$A:$A)*($A9=数据提取表!$B:$B)),数据提取表!G:G) -> 2.91 | G9: =LOOKUP(1,0/(($D$3=数据提取表!$A:$A)*($A9=数据提取表!$B:$B)),数据提取表!H:H) -> 8.5947 | H9: =LOOKUP(1,0/(($D$3=数据提取表!$A:$A)*($A9=数据提取表!$B:$B)),数据提取表!I:I) -> 8.1943 | I9: =LOOKUP(1,0/(($D$3=数据提取表!$A:$A)*($A9=数据提取表!$B:$B)),数据提取表!J:J) -> 7.92 | J9: =LOOKUP(1,0/(($D$3=数据提取表!$A:$A)*($A9=数据提取表!$B:$B)),数据提取表!K:K) -> 0 | K9: =J9/G9 -> 0 | L9: =LOOKUP(1,0/(($D$3=数据提取表!$A:$A)*($A9=数据提取表!$B:$B)),数据提取表!M:M) -> 22.44 | M9: =计划电量!O6 -> 1188 | N9: =L9-M9/31*日报辅助图!$D$1 -> -54.205161 | O9: =L9/M9 -> 0.018888889 | P9: =N9/M9 -> -0.04562724 | Q9: =L9+AG9+AH9 -> 1104.07 | R9: =计划电量!H6 -> 3712 | S9: =Q9-(计划电量!N6+计划电量!O6/31*日报辅助图!$D$1) -> -105.57516 | T9: =Q9/R9 -> 0.29743265 | U9: =S9/R9 -> -0.028441584 | V9: {=LOOKUP(1,0/(($D$3=数据提取表!$A:$A)*($A9=数据提取表!$B:$B)),数据提取表!R:R)} -> 3883.022 | W9: =计划电量!F6 -> 12700 | X9: =V9-(计划电量!G6+计划电量!N6+计划电量!O6/31*日报辅助图!$D$1) -> 135.37684 | Y9: =V9/W9 -> 0.30574976 | Z9: =X9/W9 -> 0.010659594 | AA9: {=LOOKUP(1,0/(($D$3=数据提取表!$A:$A)*($A9=数据提取表!$B:$B)),数据提取表!AC:AC)} -> 0 | AB9: {=LOOKUP(1,0/(($D$3=数据提取表!$A:$A)*($A9=数据提取表!$B:$B)),数据提取表!AD:AD)} -> 0 | AG9: 1081.63
A10: 浩屯浩风风电场 | B10: BO05 | C10: 王浩屯浩风 | D10: 50 | E10: =LOOKUP(1,0/(($D$3=数据提取表!$A:$A)*($A10=数据提取表!$B:$B)),数据提取表!E:E) -> 晴 | F10: =LOOKUP(1,0/(($D$3=数据提取表!$A:$A)*($A10=数据提取表!$B:$B)),数据提取表!G:G) -> 5.6 | G10: =LOOKUP(1,0/(($D$3=数据提取表!$A:$A)*($A10=数据提取表!$B:$B)),数据提取表!H:H) -> 30.2427 | H10: =LOOKUP(1,0/(($D$3=数据提取表!$A:$A)*($A10=数据提取表!$B:$B)),数据提取表!I:I) -> 27.0268 | I10: =LOOKUP(1,0/(($D$3=数据提取表!$A:$A)*($A10=数据提取表!$B:$B)),数据提取表!J:J) -> 25.62 | J10: =LOOKUP(1,0/(($D$3=数据提取表!$A:$A)*($A10=数据提取表!$B:$B)),数据提取表!K:K) -> 2.55 | K10: =J10/G10 -> 0.084317868 | L10: =LOOKUP(1,0/(($D$3=数据提取表!$A:$A)*($A10=数据提取表!$B:$B)),数据提取表!M:M) -> 31.71 | M10: =计划电量!O7 -> 1202 | N10: =L10-M10/31*日报辅助图!$D$1 -> -45.838387 | O10: =L10/M10 -> 0.026381032 | P10: =N10/M10 -> -0.038135097 | Q10: =L10+AG10+AH10 -> 1242.36 | R10: =计划电量!H7 -> 3439 | S10: =Q10-(计划电量!N7+计划电量!O7/31*日报辅助图!$D$1) -> -167.18839 | T10: =Q10/R10 -> 0.36125618 | U10: =S10/R10 -> -0.048615408 | V10: {=LOOKUP(1,0/(($D$3=数据提取表!$A:$A)*($A10=数据提取表!$B:$B)),数据提取表!R:R)} -> 5143.32 | W10: =计划电量!F7 -> 12070 | X10: =V10-(计划电量!G7+计划电量!N7+计划电量!O7/31*日报辅助图!$D$1) -> 241.77161 | Y10: =V10/W10 -> 0.42612428 | Z10: =X10/W10 -> 0.020030788 | AA10: {=LOOKUP(1,0/(($D$3=数据提取表!$A:$A)*($A10=数据提取表!$B:$B)),数据提取表!AC:AC)} -> 0 | AB10: {=LOOKUP(1,0/(($D$3=数据提取表!$A:$A)*($A10=数据提取表!$B:$B)),数据提取表!AD:AD)} -> 0 | AG10: 1210.65
A11: 干龙潭光伏电站 | B11: BO06 | C11: 云县干龙潭 | D11: 30 | E11: =LOOKUP(1,0/(($D$3=数据提取表!$A:$A)*($A11=数据提取表!$B:$B)),数据提取表!E:E) -> 多云 | F11: =LOOKUP(1,0/(($D$3=数据提取表!$A:$A)*($A11=数据提取表!$B:$B)),数据提取表!F:F) -> 4.3 | G11: =LOOKUP(1,0/(($D$3=数据提取表!$A:$A)*($A11=数据提取表!$B:$B)),数据提取表!H:H) -> 10.3087 | H11: =LOOKUP(1,0/(($D$3=数据提取表!$A:$A)*($A11=数据提取表!$B:$B)),数据提取表!I:I) -> 10.1097 | I11: =LOOKUP(1,0/(($D$3=数据提取表!$A:$A)*($A11=数据提取表!$B:$B)),数据提取表!J:J) -> 10.0898 | J11: =LOOKUP(1,0/(($D$3=数据提取表!$A:$A)*($A11=数据提取表!$B:$B)),数据提取表!K:K) -> 0 | K11: =J11/G11 -> 0 | L11: =LOOKUP(1,0/(($D$3=数据提取表!$A:$A)*($A11=数据提取表!$B:$B)),数据提取表!M:M) -> 17.2346 | M11: =计划电量!O8 -> 275 | N11: =L11-M11/31*日报辅助图!$D$1 -> -0.50733548 | O11: =L11/M11 -> 0.062671273 | P11: =N11/M11 -> -0.0018448563 | Q11: =L11+AG11+AH11 -> 284.2475 | R11: =计划电量!H8 -> 849 | S11: =Q11-(计划电量!N8+计划电量!O8/31*日报辅助图!$D$1) -> -82.494435 | T11: =Q11/R11 -> 0.33480271 | U11: =S11/R11 -> -0.097166591 | V11: {=LOOKUP(1,0/(($D$3=数据提取表!$A:$A)*($A11=数据提取表!$B:$B)),数据提取表!R:R)} -> 1454.5002 | W11: =计划电量!F8 -> 3672 | X11: =V11-(计划电量!G8+计划电量!N8+计划电量!O8/31*日报辅助图!$D$1) -> -171.24174 | Y11: =V11/W11 -> 0.39610572 | Z11: =X11/W11 -> -0.04663446 | AA11: {=LOOKUP(1,0/(($D$3=数据提取表!$A:$A)*($A11=数据提取表!$B:$B)),数据提取表!AC:AC)} -> 0 | AB11: {=LOOKUP(1,0/(($D$3=数据提取表!$A:$A)*($A11=数据提取表!$B:$B)),数据提取表!AD:AD)} -> 0 | AG11: 267.0129
A12: 特能星光#3光伏电站 | B12: BO07 | C12: 敦煌星光 | D12: 20 | E12: =LOOKUP(1,0/(($D$3=数据提取表!$A:$A)*($A12=数据提取表!$B:$B)),数据提取表!E:E) -> 阴 | F12: =LOOKUP(1,0/(($D$3=数据提取表!$A:$A)*($A12=数据提取表!$B:$B)),数据提取表!F:F) -> 5.13 | G12: =LOOKUP(1,0/(($D$3=数据提取表!$A:$A)*($A12=数据提取表!$B:$B)),数据提取表!H:H) -> 11.092 | H12: =LOOKUP(1,0/(($D$3=数据提取表!$A:$A)*($A12=数据提取表!$B:$B)),数据提取表!I:I) -> 0 | I12: =LOOKUP(1,0/(($D$3=数据提取表!$A:$A)*($A12=数据提取表!$B:$B)),数据提取表!J:J) -> 0 | J12: =LOOKUP(1,0/(($D$3=数据提取表!$A:$A)*($A12=数据提取表!$B:$B)),数据提取表!K:K) -> 0 | K12: =J12/G12 -> 0 | L12: =LOOKUP(1,0/(($D$3=数据提取表!$A:$A)*($A12=数据提取表!$B:$B)),数据提取表!M:M) -> 0 | M12: =计划电量!O9 -> 388 | N12: =L12-M12/31*日报辅助图!$D$1 -> -25.032258 | O12: =L12/M12 -> 0 | P12: =N12/M12 -> -0.064516129 | Q12: =L12+AG12+AH12 -> 232.7277 | R12: =计划电量!H9 -> 1113 | S12: =Q12-(计划电量!N9+计划电量!O9/31*日报辅助图!$D$1) -> -109.30456 | T12: =Q12/R12 -> 0.20909946 | U12: =S12/R12 -> -0.09820715 | V12: {=LOOKUP(1,0/(($D$3=数据提取表!$A:$A)*($A12=数据提取表!$B:$B)),数据提取表!R:R)} -> 1085.8112 | W12: =计划电量!F9 -> 4106 | X12: =V12-(计划电量!G9+计划电量!N9+计划电量!O9/31*日报辅助图!$D$1) -> -170.22106 | Y12: =V12/W12 -> 0.26444501 | Z12: =X12/W12 -> -0.041456663 | AA12: {=LOOKUP(1,0/(($D$3=数据提取表!$A:$A)*($A12=数据提取表!$B:$B)),数据提取表!AC:AC)} -> 0 | AB12: {=LOOKUP(1,0/(($D$3=数据提取表!$A:$A)*($A12=数据提取表!$B:$B)),数据提取表!AD:AD)} -> 0 | AG12: 232.7277
A13: 高传官滩风力发电厂 | B13: BO08 | C13: 盱眙官滩 | D13: 80 | E13: =LOOKUP(1,0/(($D$3=数据提取表!$A:$A)*($A13=数据提取表!$B:$B)),数据提取表!E:E) -> 阴 | F13: =LOOKUP(1,0/(($D$3=数据提取表!$A:$A)*($A13=数据提取表!$B:$B)),数据提取表!G:G) -> 3.72 | G13: =LOOKUP(1,0/(($D$3=数据提取表!$A:$A)*($A13=数据提取表!$B:$B)),数据提取表!H:H) -> 18.722 | H13: =LOOKUP(1,0/(($D$3=数据提取表!$A:$A)*($A13=数据提取表!$B:$B)),数据提取表!I:I) -> 18.4729 | I13: =LOOKUP(1,0/(($D$3=数据提取表!$A:$A)*($A13=数据提取表!$B:$B)),数据提取表!J:J) -> 17.5119 | J13: =LOOKUP(1,0/(($D$3=数据提取表!$A:$A)*($A13=数据提取表!$B:$B)),数据提取表!K:K) -> 0 | K13: =J13/G13 -> 0 | L13: =LOOKUP(1,0/(($D$3=数据提取表!$A:$A)*($A13=数据提取表!$B:$B)),数据提取表!M:M) -> 25.5375 | M13: =计划电量!O10 -> 1483 | N13: =L13-M13/31*日报辅助图!$D$1 -> -70.139919 | O13: =L13/M13 -> 0.017220162 | P13: =N13/M13 -> -0.047295967 | Q13: =L13+AG13+AH13 -> 1431.3361 | R13: =计划电量!H10 -> 4437 | S13: =Q13-(计划电量!N10+计划电量!O10/31*日报辅助图!$D$1) -> -305.34132 | T13: =Q13/R13 -> 0.32259096 | U13: =S13/R13 -> -0.068817065 | V13: {=LOOKUP(1,0/(($D$3=数据提取表!$A:$A)*($A13=数据提取表!$B:$B)),数据提取表!R:R)} -> 7120.7777 | W13: =计划电量!F10 -> 18237 | X13: =V13-(计划电量!G10+计划电量!N10+计划电量!O10/31*日报辅助图!$D$1) -> -301.89972 | Y13: =V13/W13 -> 0.39045773 | Z13: =X13/W13 -> -0.016554242 | AA13: {=LOOKUP(1,0/(($D$3=数据提取表!$A:$A)*($A13=数据提取表!$B:$B)),数据提取表!AC:AC)} -> 0 | AB13: {=LOOKUP(1,0/(($D$3=数据提取表!$A:$A)*($A13=数据提取表!$B:$B)),数据提取表!AD:AD)} -> 0 | AG13: 1405.7986
A14: 子牙关光伏电站 | B14: BO09 | C14: 鹤庆子牙关 | D14: 30 | E14: =LOOKUP(1,0/(($D$3=数据提取表!$A:$A)*($A14=数据提取表!$B:$B)),数据提取表!E:E) -> 阴 | F14: =LOOKUP(1,0/(($D$3=数据提取表!$A:$A)*($A14=数据提取表!$B:$B)),数据提取表!F:F) -> 3.6 | G14: =LOOKUP(1,0/(($D$3=数据提取表!$A:$A)*($A14=数据提取表!$B:$B)),数据提取表!H:H) -> 8.9393 | H14: =LOOKUP(1,0/(($D$3=数据提取表!$A:$A)*($A14=数据提取表!$B:$B)),数据提取表!I:I) -> 8.764 | I14: =LOOKUP(1,0/(($D$3=数据提取表!$A:$A)*($A14=数据提取表!$B:$B)),数据提取表!J:J) -> 8.736 | J14: =LOOKUP(1,0/(($D$3=数据提取表!$A:$A)*($A14=数据提取表!$B:$B)),数据提取表!K:K) -> 0 | K14: =J14/G14 -> 0 | L14: =LOOKUP(1,0/(($D$3=数据提取表!$A:$A)*($A14=数据提取表!$B:$B)),数据提取表!M:M) -> 21.56 | M14: =计划电量!O11 -> 412 | N14: =L14-M14/31*日报辅助图!$D$1 -> -5.0206452 | O14: =L14/M14 -> 0.052330097 | P14: =N14/M14 -> -0.012186032 | Q14: =L14+AG14+AH14 -> 402.584 | R14: =计划电量!H11 -> 1147 | S14: =Q14-(计划电量!N11+计划电量!O11/31*日报辅助图!$D$1) -> -38.996645 | T14: =Q14/R14 -> 0.35098867 | U14: =S14/R14 -> -0.033998819 | V14: {=LOOKUP(1,0/(($D$3=数据提取表!$A:$A)*($A14=数据提取表!$B:$B)),数据提取表!R:R)} -> 1724.912 | W14: =计划电量!F11 -> 4708 | X14: =V14-(计划电量!G11+计划电量!N11+计划电量!O11/31*日报辅助图!$D$1) -> -4.6686452 | Y14: =V14/W14 -> 0.36637893 | Z14: =X14/W14 -> -0.00099164086 | AA14: {=LOOKUP(1,0/(($D$3=数据提取表!$A:$A)*($A14=数据提取表!$B:$B)),数据提取表!AC:AC)} -> 0 | AB14: {=LOOKUP(1,0/(($D$3=数据提取表!$A:$A)*($A14=数据提取表!$B:$B)),数据提取表!AD:AD)} -> 0 | AG14: 381.024
A15: 恒泰风电场 | B15: BO10 | C15: 穆店恒泰 | D15: 20 | E15: =LOOKUP(1,0/(($D$3=数据提取表!$A:$A)*($A15=数据提取表!$B:$B)),数据提取表!E:E) -> 晴 | F15: =LOOKUP(1,0/(($D$3=数据提取表!$A:$A)*($A15=数据提取表!$B:$B)),数据提取表!G:G) -> 4.15 | G15: =LOOKUP(1,0/(($D$3=数据提取表!$A:$A)*($A15=数据提取表!$B:$B)),数据提取表!H:H) -> 11.2686 | H15: =LOOKUP(1,0/(($D$3=数据提取表!$A:$A)*($A15=数据提取表!$B:$B)),数据提取表!I:I) -> 11.046 | I15: =LOOKUP(1,0/(($D$3=数据提取表!$A:$A)*($A15=数据提取表!$B:$B)),数据提取表!J:J) -> 11.0208 | J15: =LOOKUP(1,0/(($D$3=数据提取表!$A:$A)*($A15=数据提取表!$B:$B)),数据提取表!K:K) -> 0.1658 | K15: =J15/G15 -> 0.014713452 | L15: =LOOKUP(1,0/(($D$3=数据提取表!$A:$A)*($A15=数据提取表!$B:$B)),数据提取表!M:M) -> 13.025 | M15: =计划电量!O12 -> 490 | N15: =L15-M15/31*日报辅助图!$D$1 -> -18.587903 | O15: =L15/M15 -> 0.026581633 | P15: =N15/M15 -> -0.037934496 | Q15: =L15+AG15+AH15 -> 442.084 | R15: =计划电量!H12 -> 1569 | S15: =Q15-(计划电量!N12+计划电量!O12/31*日报辅助图!$D$1) -> -221.5289 | T15: =Q15/R15 -> 0.28176163 | U15: =S15/R15 -> -0.14119114 | V15: {=LOOKUP(1,0/(($D$3=数据提取表!$A:$A)*($A15=数据提取表!$B:$B)),数据提取表!R:R)} -> 2070.2761 | W15: =计划电量!F12 -> 5372 | X15: =V15-(计划电量!G12+计划电量!N12+计划电量!O12/31*日报辅助图!$D$1) -> -15.336803 | Y15: =V15/W15 -> 0.38538274 | Z15: =X15/W15 -> -0.0028549522 | AA15: {=LOOKUP(1,0/(($D$3=数据提取表!$A:$A)*($A15=数据提取表!$B:$B)),数据提取表!AC:AC)} -> 0 | AB15: {=LOOKUP(1,0/(($D$3=数据提取表!$A:$A)*($A15=数据提取表!$B:$B)),数据提取表!AD:AD)} -> 0 | AG15: 429.059
A16: 武晟庄华光伏电站 | B16: BO11 | C16: 武威武晟 | D16: 180 | E16: =LOOKUP(1,0/(($D$3=数据提取表!$A:$A)*($A16=数据提取表!$B:$B)),数据提取表!E:E) -> 晴转多云 | F16: =LOOKUP(1,0/(($D$3=数据提取表!$A:$A)*($A16=数据提取表!$B:$B)),数据提取表!F:F) -> 7.01 | G16: =LOOKUP(1,0/(($D$3=数据提取表!$A:$A)*($A16=数据提取表!$B:$B)),数据提取表!H:H) -> 106.5716 | H16: =LOOKUP(1,0/(($D$3=数据提取表!$A:$A)*($A16=数据提取表!$B:$B)),数据提取表!I:I) -> 71.1386 | I16: =LOOKUP(1,0/(($D$3=数据提取表!$A:$A)*($A16=数据提取表!$B:$B)),数据提取表!J:J) -> 73.7961 | J16: =LOOKUP(1,0/(($D$3=数据提取表!$A:$A)*($A16=数据提取表!$B:$B)),数据提取表!K:K) -> 35.43 | K16: =J16/G16 -> 0.33245255 | L16: =LOOKUP(1,0/(($D$3=数据提取表!$A:$A)*($A16=数据提取表!$B:$B)),数据提取表!M:M) -> 161.273 | M16: =计划电量!O13 -> 2714 | N16: =L16-M16/31*日报辅助图!$D$1 -> -13.823774 | O16: =L16/M16 -> 0.059422623 | P16: =N16/M16 -> -0.0050935056 | Q16: =L16+AG16+AH16 -> 1591.6719 | R16: =计划电量!H13 -> 7883 | S16: =Q16-(计划电量!N13+计划电量!O13/31*日报辅助图!$D$1) -> -1063.4249 | T16: =Q16/R16 -> 0.20191195 | U16: =S16/R16 -> -0.13490104 | V16: {=LOOKUP(1,0/(($D$3=数据提取表!$A:$A)*($A16=数据提取表!$B:$B)),数据提取表!R:R)} -> 5656.0056 | W16: =计划电量!F13 -> 24402 | X16: =V16-(计划电量!G13+计划电量!N13+计划电量!O13/31*日报辅助图!$D$1) -> -1737.0912 | Y16: =V16/W16 -> 0.23178451 | Z16: =X16/W16 -> -0.071186426 | AA16: {=LOOKUP(1,0/(($D$3=数据提取表!$A:$A)*($A16=数据提取表!$B:$B)),数据提取表!AC:AC)} -> 0 | AB16: {=LOOKUP(1,0/(($D$3=数据提取表!$A:$A)*($A16=数据提取表!$B:$B)),数据提取表!AD:AD)} -> 0 | AG16: 1430.3989
A17: 100MW星奥光伏电站 | B17: BO12 | C17: 敦煌星奥 | D17: 100 | E17: =LOOKUP(1,0/(($D$3=数据提取表!$A:$A)*($A17=数据提取表!$B:$B)),数据提取表!E:E) -> 阴 | F17: =LOOKUP(1,0/(($D$3=数据提取表!$A:$A)*($A17=数据提取表!$B:$B)),数据提取表!F:F) -> 5.41 | G17: =LOOKUP(1,0/(($D$3=数据提取表!$A:$A)*($A17=数据提取表!$B:$B)),数据提取表!H:H) -> 53.8407 | H17: =LOOKUP(1,0/(($D$3=数据提取表!$A:$A)*($A17=数据提取表!$B:$B)),数据提取表!I:I) -> 34.7005 | I17: =LOOKUP(1,0/(($D$3=数据提取表!$A:$A)*($A17=数据提取表!$B:$B)),数据提取表!J:J) -> 32.865 | J17: =LOOKUP(1,0/(($D$3=数据提取表!$A:$A)*($A17=数据提取表!$B:$B)),数据提取表!K:K) -> 19.1402 | K17: =J17/G17 -> 0.35549686 | L17: =LOOKUP(1,0/(($D$3=数据提取表!$A:$A)*($A17=数据提取表!$B:$B)),数据提取表!M:M) -> 96.467 | M17: =计划电量!O14 -> 2401 | N17: =L17-M17/31*日报辅助图!$D$1 -> -58.436226 | O17: =L17/M17 -> 0.040177843 | P17: =N17/M17 -> -0.024338286 | Q17: =L17+AG17+AH17 -> 1280.734 | R17: =计划电量!H14 -> 6761 | S17: =Q17-(计划电量!N14+计划电量!O14/31*日报辅助图!$D$1) -> -974.16923 | T17: =Q17/R17 -> 0.18942967 | U17: =S17/R17 -> -0.14408656 | V17: {=LOOKUP(1,0/(($D$3=数据提取表!$A:$A)*($A17=数据提取表!$B:$B)),数据提取表!R:R)} -> 3913.581 | W17: =计划电量!F14 -> 17591 | X17: =V17-(计划电量!G14+计划电量!N14+计划电量!O14/31*日报辅助图!$D$1) -> 253.67777 | Y17: =V17/W17 -> 0.22247632 | Z17: =X17/W17 -> 0.014420884 | AA17: {=LOOKUP(1,0/(($D$3=数据提取表!$A:$A)*($A17=数据提取表!$B:$B)),数据提取表!AC:AC)} -> 0 | AB17: {=LOOKUP(1,0/(($D$3=数据提取表!$A:$A)*($A17=数据提取表!$B:$B)),数据提取表!AD:AD)} -> 0 | AG17: 1184.267
B18: 存量项目小计 | D18: =SUM(D6:D17) -> 760 | E18: / | F18: / | G18: =SUM(G6:G17) -> 386.7507 | H18: =SUM(H6:H17) -> 299.4228 | I18: =SUM(I6:I17) -> 297.1596 | J18: =SUM(J6:J17) -> 72.8616 | K18: =J18/G18 -> 0.18839423 | L18: =SUM(L6:L17) -> 600.8671 | M18: =SUM(M6:M17) -> 13311 | N18: =SUM(N6:N17) -> -257.90709 | O18: =L18/M18 -> 0.045140643 | P18: =N18/M18 -> -0.019375486 | Q18: =SUM(Q6:Q17) -> 10783.67 | R18: =SUM(R6:R17) -> 39185.4 | S18: =SUM(S6:S17) -> -2983.504 | T18: =Q18/R18 -> 0.27519612 | U18: =S18/R18 -> -0.076138153 | V18: =SUM(V6:V17) -> 40715.798 | W18: =SUM(W6:W17) -> 131795.4 | X18: =SUM(X6:X17) -> -2645.3759 | Y18: =V18/W18 -> 0.30893186 | Z18: =X18/W18 -> -0.020071838 | AA18: =SUM(AA6:AA17) -> 0 | AB18: =SUM(AB6:AB17) -> 0 | AG18: 10182.803
A19: 军红风电场 | B19: BO13 | C19: 舞阳军红 | D19: 100 | E19: =LOOKUP(1,0/(($D$3=数据提取表!$A:$A)*($A19=数据提取表!$B:$B)),数据提取表!E:E) -> 晴 | F19: {=LOOKUP(1,0/(($D$3=数据提取表!$A:$A)*($A19=数据提取表!$B:$B)),数据提取表!G:G)} -> 3.79 | G19: {=LOOKUP(1,0/(($D$3=数据提取表!$A:$A)*($A19=数据提取表!$B:$B)),数据提取表!H:H)} -> 0 | H19: {=LOOKUP(1,0/(($D$3=数据提取表!$A:$A)*($A19=数据提取表!$B:$B)),数据提取表!I:I)} -> 12.81 | I19: =LOOKUP(1,0/(($D$3=数据提取表!$A:$A)*($A19=数据提取表!$B:$B)),数据提取表!J:J) -> 12.3464 | J19: =LOOKUP(1,0/(($D$3=数据提取表!$A:$A)*($A19=数据提取表!$B:$B)),数据提取表!K:K) -> 0 | K19: 0 | L19: =LOOKUP(1,0/(($D$3=数据提取表!$A:$A)*($A19=数据提取表!$B:$B)),数据提取表!M:M) -> 17.336 | M19: =计划电量!O15 -> 1500 | N19: =L19-M19/31*日报辅助图!$D$1 -> -79.438194 | O19: =L19/M19 -> 0.011557333 | P19: =N19/M19 -> -0.052958796 | Q19: =L19+AG19+AH19 -> 354.6928 | R19: =计划电量!H15 -> 5346 | S19: =Q19-(计划电量!N15+计划电量!O15/31*日报辅助图!$D$1) -> -1982.0814 | T19: =Q19/R19 -> 0.066347325 | U19: =S19/R19 -> -0.37075971 | V19: {=LOOKUP(1,0/(($D$3=数据提取表!$A:$A)*($A19=数据提取表!$B:$B)),数据提取表!R:R)} -> 660.7876 | W19: =计划电量!F15 -> 14500.6 | X19: =V19-(计划电量!G15+计划电量!N15+计划电量!O15/31*日报辅助图!$D$1) -> -3760.9866 | Y19: =V19/W19 -> 0.045569673 | Z19: =X19/W19 -> -0.25936765 | AA19: {=LOOKUP(1,0/(($D$3=数据提取表!$A:$A)*($A19=数据提取表!$B:$B)),数据提取表!AC:AC)} -> 0 | AB19: {=LOOKUP(1,0/(($D$3=数据提取表!$A:$A)*($A19=数据提取表!$B:$B)),数据提取表!AD:AD)} -> 0 | AG19: 337.3568
B20: BO14 | C20: 永城一期 | D20: 100 | E20: =LOOKUP(1,0/(($D$3=数据提取表!$A:$A)*($A20=数据提取表!$B:$B)),数据提取表!E:E) -> #N/A | F20: =LOOKUP(1,0/(($D$3=数据提取表!$A:$A)*($A20=数据提取表!$B:$B)),数据提取表!F:F) -> #N/A | G20: =LOOKUP(1,0/(($D$3=数据提取表!$A:$A)*($A20=数据提取表!$B:$B)),数据提取表!H:H) -> #N/A | H20: =LOOKUP(1,0/(($D$3=数据提取表!$A:$A)*($A20=数据提取表!$B:$B)),数据提取表!I:I) -> #N/A | I20: =LOOKUP(1,0/(($D$3=数据提取表!$A:$A)*($A20=数据提取表!$B:$B)),数据提取表!J:J) -> #N/A | J20: =LOOKUP(1,0/(($D$3=数据提取表!$A:$A)*($A20=数据提取表!$B:$B)),数据提取表!K:K) -> #N/A | K20: =J20/G20 -> #N/A | L20: =LOOKUP(1,0/(($D$3=数据提取表!$A:$A)*($A20=数据提取表!$B:$B)),数据提取表!M:M) -> #N/A | M20: =计划电量!N16 -> 0 | N20: =L20-M20/31*日报辅助图!$D$1 -> #N/A | O20: =L20/M20 -> #N/A | P20: =N20/M20 -> #N/A | Q20: =L20 -> #N/A | R20: =计划电量!H16 -> 0 | S20: =Q20-(计划电量!K16/31*日报辅助图!$D$1) -> #N/A | T20: =Q20/R20 -> #N/A | U20: =S20/R20 -> #N/A | V20: {=LOOKUP(1,0/(($D$3=数据提取表!$A:$A)*($A20=数据提取表!$B:$B)),数据提取表!R:R)} -> #N/A | W20: 5321.6 | X20: =V20-(计划电量!K16/31*日报辅助图!$D$1) -> #N/A | Y20: =V20/W20 -> #N/A | Z20: =X20/W20 -> #N/A | AA20: {=LOOKUP(1,0/(($D$3=数据提取表!$A:$A)*($A20=数据提取表!$B:$B)),数据提取表!AC:AC)} -> #N/A | AB20: {=LOOKUP(1,0/(($D$3=数据提取表!$A:$A)*($A20=数据提取表!$B:$B)),数据提取表!AD:AD)} -> #N/A | AG20: #N/A
B21: BO15 | C21: 永城二期 | D21: 100 | E21: =LOOKUP(1,0/(($D$3=数据提取表!$A:$A)*($A21=数据提取表!$B:$B)),数据提取表!E:E) -> #N/A | F21: =LOOKUP(1,0/(($D$3=数据提取表!$A:$A)*($A21=数据提取表!$B:$B)),数据提取表!F:F) -> #N/A | G21: =LOOKUP(1,0/(($D$3=数据提取表!$A:$A)*($A21=数据提取表!$B:$B)),数据提取表!H:H) -> #N/A | H21: =LOOKUP(1,0/(($D$3=数据提取表!$A:$A)*($A21=数据提取表!$B:$B)),数据提取表!I:I) -> #N/A | I21: =LOOKUP(1,0/(($D$3=数据提取表!$A:$A)*($A21=数据提取表!$B:$B)),数据提取表!J:J) -> #N/A | J21: =LOOKUP(1,0/(($D$3=数据提取表!$A:$A)*($A21=数据提取表!$B:$B)),数据提取表!K:K) -> #N/A | K21: =J21/G21 -> #N/A | L21: =LOOKUP(1,0/(($D$3=数据提取表!$A:$A)*($A21=数据提取表!$B:$B)),数据提取表!M:M) -> #N/A | M21: =计划电量!N17 -> 0 | N21: =L21-M21/31*日报辅助图!$D$1 -> #N/A | O21: =L21/M21 -> #N/A | P21: =N21/M21 -> #N/A | Q21: =L21 -> #N/A | R21: =计划电量!H17 -> 0 | S21: =Q21-(计划电量!K17/31*日报辅助图!$D$1) -> #N/A | T21: =Q21/R21 -> #N/A | U21: =S21/R21 -> #N/A | V21: {=LOOKUP(1,0/(($D$3=数据提取表!$A:$A)*($A21=数据提取表!$B:$B)),数据提取表!R:R)} -> #N/A | W21: 6763 | X21: =V21-(计划电量!K17/31*日报辅助图!$D$1) -> #N/A | Y21: =V21/W21 -> #N/A | Z21: =X21/W21 -> #N/A | AA21: {=LOOKUP(1,0/(($D$3=数据提取表!$A:$A)*($A21=数据提取表!$B:$B)),数据提取表!AC:AC)} -> #N/A | AB21: {=LOOKUP(1,0/(($D$3=数据提取表!$A:$A)*($A21=数据提取表!$B:$B)),数据提取表!AD:AD)} -> #N/A | AG21: #N/A
B22: BO16 | C22: 遂川风电 | D22: 40 | E22: =LOOKUP(1,0/(($D$3=数据提取表!$A:$A)*($A22=数据提取表!$B:$B)),数据提取表!E:E) -> #N/A | F22: =LOOKUP(1,0/(($D$3=数据提取表!$A:$A)*($A22=数据提取表!$B:$B)),数据提取表!F:F) -> #N/A | G22: =LOOKUP(1,0/(($D$3=数据提取表!$A:$A)*($A22=数据提取表!$B:$B)),数据提取表!H:H) -> #N/A | H22: =LOOKUP(1,0/(($D$3=数据提取表!$A:$A)*($A22=数据提取表!$B:$B)),数据提取表!I:I) -> #N/A | I22: =LOOKUP(1,0/(($D$3=数据提取表!$A:$A)*($A22=数据提取表!$B:$B)),数据提取表!J:J) -> #N/A | J22: =LOOKUP(1,0/(($D$3=数据提取表!$A:$A)*($A22=数据提取表!$B:$B)),数据提取表!K:K) -> #N/A | K22: =J22/G22 -> #N/A | L22: =LOOKUP(1,0/(($D$3=数据提取表!$A:$A)*($A22=数据提取表!$B:$B)),数据提取表!M:M) -> #N/A | M22: =计划电量!N18 -> 124 | N22: =L22-M22/31*日报辅助图!$D$1 -> #N/A | O22: =L22/M22 -> #N/A | P22: =N22/M22 -> #N/A | Q22: =L22 -> #N/A | R22: =计划电量!H18 -> 1109 | S22: =Q22-(计划电量!K18/31*日报辅助图!$D$1) -> #N/A | T22: =Q22/R22 -> #N/A | U22: =S22/R22 -> #N/A | V22: {=LOOKUP(1,0/(($D$3=数据提取表!$A:$A)*($A22=数据提取表!$B:$B)),数据提取表!R:R)} -> #N/A | W22: 6476 | X22: =V22-(计划电量!K18/31*日报辅助图!$D$1) -> #N/A | Y22: =V22/W22 -> #N/A | Z22: =X22/W22 -> #N/A | AA22: {=LOOKUP(1,0/(($D$3=数据提取表!$A:$A)*($A22=数据提取表!$B:$B)),数据提取表!AC:AC)} -> #N/A | AB22: {=LOOKUP(1,0/(($D$3=数据提取表!$A:$A)*($A22=数据提取表!$B:$B)),数据提取表!AD:AD)} -> #N/A | AG22: #N/A
B23: BO17 | C23: 泗县风电 | D23: 100 | E23: =LOOKUP(1,0/(($D$3=数据提取表!$A:$A)*($A23=数据提取表!$B:$B)),数据提取表!E:E) -> #N/A | F23: =LOOKUP(1,0/(($D$3=数据提取表!$A:$A)*($A23=数据提取表!$B:$B)),数据提取表!F:F) -> #N/A | G23: =LOOKUP(1,0/(($D$3=数据提取表!$A:$A)*($A23=数据提取表!$B:$B)),数据提取表!H:H) -> #N/A | H23: =LOOKUP(1,0/(($D$3=数据提取表!$A:$A)*($A23=数据提取表!$B:$B)),数据提取表!I:I) -> #N/A | I23: =LOOKUP(1,0/(($D$3=数据提取表!$A:$A)*($A23=数据提取表!$B:$B)),数据提取表!J:J) -> #N/A | J23: =LOOKUP(1,0/(($D$3=数据提取表!$A:$A)*($A23=数据提取表!$B:$B)),数据提取表!K:K) -> #N/A | K23: =J23/G23 -> #N/A | L23: =LOOKUP(1,0/(($D$3=数据提取表!$A:$A)*($A23=数据提取表!$B:$B)),数据提取表!M:M) -> #N/A | M23: =计划电量!N19 -> 0 | N23: =L23-M23/31*日报辅助图!$D$1 -> #N/A | O23: =L23/M23 -> #N/A | P23: =N23/M23 -> #N/A | Q23: =L23 -> #N/A | R23: =计划电量!H19 -> 0 | S23: =Q23-(计划电量!K19/31*日报辅助图!$D$1) -> #N/A | T23: =Q23/R23 -> #N/A | U23: =S23/R23 -> #N/A | V23: {=LOOKUP(1,0/(($D$3=数据提取表!$A:$A)*($A23=数据提取表!$B:$B)),数据提取表!R:R)} -> #N/A | W23: 6684 | X23: =V23-(计划电量!K19/31*日报辅助图!$D$1) -> #N/A | Y23: =V23/W23 -> #N/A | Z23: =X23/W23 -> #N/A | AA23: {=LOOKUP(1,0/(($D$3=数据提取表!$A:$A)*($A23=数据提取表!$B:$B)),数据提取表!AC:AC)} -> #N/A | AB23: {=LOOKUP(1,0/(($D$3=数据提取表!$A:$A)*($A23=数据提取表!$B:$B)),数据提取表!AD:AD)} -> #N/A | AG23: #N/A
B24: BO18 | C24: 坛勒风电 | D24: 50 | E24: =LOOKUP(1,0/(($D$3=数据提取表!$A:$A)*($A24=数据提取表!$B:$B)),数据提取表!E:E) -> #N/A | F24: =LOOKUP(1,0/(($D$3=数据提取表!$A:$A)*($A24=数据提取表!$B:$B)),数据提取表!F:F) -> #N/A | G24: =LOOKUP(1,0/(($D$3=数据提取表!$A:$A)*($A24=数据提取表!$B:$B)),数据提取表!H:H) -> #N/A | H24: =LOOKUP(1,0/(($D$3=数据提取表!$A:$A)*($A24=数据提取表!$B:$B)),数据提取表!I:I) -> #N/A | I24: =LOOKUP(1,0/(($D$3=数据提取表!$A:$A)*($A24=数据提取表!$B:$B)),数据提取表!J:J) -> #N/A | J24: =LOOKUP(1,0/(($D$3=数据提取表!$A:$A)*($A24=数据提取表!$B:$B)),数据提取表!K:K) -> #N/A | K24: =J24/G24 -> #N/A | L24: =LOOKUP(1,0/(($D$3=数据提取表!$A:$A)*($A24=数据提取表!$B:$B)),数据提取表!M:M) -> #N/A | M24: =计划电量!N20 -> 0 | N24: =L24-M24/31*日报辅助图!$D$1 -> #N/A | O24: =L24/M24 -> #N/A | P24: =N24/M24 -> #N/A | Q24: =L24 -> #N/A | R24: =计划电量!H20 -> 0 | S24: =Q24-(计划电量!K20/31*日报辅助图!$D$1) -> #N/A | T24: =Q24/R24 -> #N/A | U24: =S24/R24 -> #N/A | V24: {=LOOKUP(1,0/(($D$3=数据提取表!$A:$A)*($A24=数据提取表!$B:$B)),数据提取表!R:R)} -> #N/A | W24: 3474 | X24: =V24-(计划电量!K20/31*日报辅助图!$D$1) -> #N/A | Y24: =V24/W24 -> #N/A | Z24: =X24/W24 -> #N/A | AA24: {=LOOKUP(1,0/(($D$3=数据提取表!$A:$A)*($A24=数据提取表!$B:$B)),数据提取表!AC:AC)} -> #N/A | AB24: {=LOOKUP(1,0/(($D$3=数据提取表!$A:$A)*($A24=数据提取表!$B:$B)),数据提取表!AD:AD)} -> #N/A | AG24: #N/A
B25: BO19 | C25: 武威二期 | D25: 100 | E25: =LOOKUP(1,0/(($D$3=数据提取表!$A:$A)*($A25=数据提取表!$B:$B)),数据提取表!E:E) -> #N/A | F25: =LOOKUP(1,0/(($D$3=数据提取表!$A:$A)*($A25=数据提取表!$B:$B)),数据提取表!F:F) -> #N/A | G25: =LOOKUP(1,0/(($D$3=数据提取表!$A:$A)*($A25=数据提取表!$B:$B)),数据提取表!H:H) -> #N/A | H25: =LOOKUP(1,0/(($D$3=数据提取表!$A:$A)*($A25=数据提取表!$B:$B)),数据提取表!I:I) -> #N/A | I25: =LOOKUP(1,0/(($D$3=数据提取表!$A:$A)*($A25=数据提取表!$B:$B)),数据提取表!J:J) -> #N/A | J25: =LOOKUP(1,0/(($D$3=数据提取表!$A:$A)*($A25=数据提取表!$B:$B)),数据提取表!K:K) -> #N/A | K25: =J25/G25 -> #N/A | L25: =LOOKUP(1,0/(($D$3=数据提取表!$A:$A)*($A25=数据提取表!$B:$B)),数据提取表!M:M) -> #N/A | M25: =计划电量!N21 -> 0 | N25: =L25-M25/31*日报辅助图!$D$1 -> #N/A | O25: =L25/M25 -> #N/A | P25: =N25/M25 -> #N/A | Q25: =L25 -> #N/A | R25: =计划电量!H21 -> 0 | S25: =Q25-(计划电量!K21/31*日报辅助图!$D$1) -> #N/A | T25: =Q25/R25 -> #N/A | U25: =S25/R25 -> #N/A | V25: {=LOOKUP(1,0/(($D$3=数据提取表!$A:$A)*($A25=数据提取表!$B:$B)),数据提取表!R:R)} -> #N/A | W25: 3820 | X25: =V25-(计划电量!K21/31*日报辅助图!$D$1) -> #N/A | Y25: =V25/W25 -> #N/A | Z25: =X25/W25 -> #N/A | AA25: {=LOOKUP(1,0/(($D$3=数据提取表!$A:$A)*($A25=数据提取表!$B:$B)),数据提取表!AC:AC)} -> #N/A | AB25: {=LOOKUP(1,0/(($D$3=数据提取表!$A:$A)*($A25=数据提取表!$B:$B)),数据提取表!AD:AD)} -> #N/A | AG25: #N/A
B26: 增量项目小计 | D26: =D19 -> 100 | E26: / | F26: / | G26: =G19 -> 0 | H26: =H19 -> 12.81 | I26: =I19 -> 12.3464 | J26: =J19 -> 0 | K26: 0 | L26: =L19 -> 17.336 | M26: =M19 -> 1500 | N26: =N19 -> -79.438194 | O26: =L26/M26 -> 0.011557333 | P26: =N26/M26 -> -0.052958796 | Q26: =Q19 -> 354.6928 | R26: =R19 -> 5346 | S26: =S19 -> -1982.0814 | T26: =Q26/R26 -> 0.066347325 | U26: =S26/R26 -> -0.37075971 | V26: =V19 -> 660.7876 | W26: =W19 -> 14500.6 | X26: =X19 -> -3760.9866 | Y26: =V26/W26 -> 0.045569673 | Z26: =X26/W26 -> -0.25936765 | AA26: =AA19 -> 0 | AB26: =AB19 -> 0 | AG26: 337.3568
B27: 南方资产运营中心小计 | D27: =D18+D26 -> 860 | E27: / | F27: / | G27: =G18+G26 -> 386.7507 | H27: =H18+H26 -> 312.2328 | I27: =I18+I26 -> 309.506 | J27: =J18+J26 -> 72.8616 | K27: =J27/G27 -> 0.18839423 | L27: =L18+L26 -> 618.2031 | M27: =M18+M26 -> 14811 | N27: =N18+N26 -> -337.34529 | O27: =L27/M27 -> 0.041739457 | P27: =N27/M27 -> -0.022776672 | Q27: =Q18+Q26 -> 11138.363 | R27: =R18+R26 -> 44531.4 | S27: =S18+S26 -> -4965.5854 | T27: =Q27/R27 -> 0.2501238 | U27: =S27/R27 -> -0.11150751 | V27: =V18+V26 -> 41376.586 | W27: =W18+W26 -> 146296 | X27: =X18+X26 -> -6406.3625 | Y27: =V27/W27 -> 0.28282787 | Z27: =X27/W27 -> -0.043790415 | AA27: =AA18+AA26 -> 0 | AB27: =AB18+AB26 -> 0 | AG27: 10520.16
A28: 固阳风源桑欧风光电站风 | B28: BO20 | C28: 固阳桑欧风电 | D28: 100 | E28: =LOOKUP(1,0/(($D$3=数据提取表!$A:$A)*($A28=数据提取表!$B:$B)),数据提取表!E:E) -> 晴 | F28: {=LOOKUP(1,0/(($D$3=数据提取表!$A:$A)*($A28=数据提取表!$B:$B)),数据提取表!G:G)} -> 7.19 | G28: =LOOKUP(1,0/(($D$3=数据提取表!$A:$A)*($A28=数据提取表!$B:$B)),数据提取表!H:H) -> 127.2725 | H28: =LOOKUP(1,0/(($D$3=数据提取表!$A:$A)*($A28=数据提取表!$B:$B)),数据提取表!I:I) -> 107.9536 | I28: =LOOKUP(1,0/(($D$3=数据提取表!$A:$A)*($A28=数据提取表!$B:$B)),数据提取表!J:J) -> 105.8714 | J28: =LOOKUP(1,0/(($D$3=数据提取表!$A:$A)*($A28=数据提取表!$B:$B)),数据提取表!K:K) -> 19.3189 | K28: =J28/G28 -> 0.15179163 | L28: =LOOKUP(1,0/(($D$3=数据提取表!$A:$A)*($A28=数据提取表!$B:$B)),数据提取表!M:M) -> 165.21 | M28: =计划电量!O23 -> 2910 | N28: =L28-M28/31*日报辅助图!$D$1 -> -22.531935 | O28: =L28/M28 -> 0.056773196 | P28: =N28/M28 -> -0.0077429332 | Q28: =L28+AG28+AH28 -> 2726.2248 | R28: =计划电量!H23 -> 8100 | S28: =Q28-(计划电量!N23+计划电量!O23/31*日报辅助图!$D$1) -> -187.51714 | T28: =Q28/R28 -> 0.33657096 | U28: =S28/R28 -> -0.023150264 | V28: {=LOOKUP(1,0/(($D$3=数据提取表!$A:$A)*($A28=数据提取表!$B:$B)),数据提取表!R:R)} -> 9085.0147 | W28: =计划电量!F23 -> 28860 | X28: =V28-(计划电量!G23+计划电量!N23+计划电量!O23/31*日报辅助图!$D$1) -> -928.72724 | Y28: =V28/W28 -> 0.31479607 | Z28: =X28/W28 -> -0.032180431 | AA28: {=LOOKUP(1,0/(($D$3=数据提取表!$A:$A)*($A28=数据提取表!$B:$B)),数据提取表!AC:AC)} -> 0 | AB28: {=LOOKUP(1,0/(($D$3=数据提取表!$A:$A)*($A28=数据提取表!$B:$B)),数据提取表!AD:AD)} -> 0 | AG28: 2561.0148
A29: 固阳风源桑欧风光电站光 | B29: BO21 | C29: 固阳桑欧光伏 | D29: 20 | E29: =LOOKUP(1,0/(($D$3=数据提取表!$A:$A)*($A29=数据提取表!$B:$B)),数据提取表!E:E) -> 晴 | F29: =LOOKUP(1,0/(($D$3=数据提取表!$A:$A)*($A29=数据提取表!$B:$B)),数据提取表!F:F) -> 7.49 | G29: =LOOKUP(1,0/(($D$3=数据提取表!$A:$A)*($A29=数据提取表!$B:$B)),数据提取表!H:H) -> 13.791 | H29: =LOOKUP(1,0/(($D$3=数据提取表!$A:$A)*($A29=数据提取表!$B:$B)),数据提取表!I:I) -> 12.8608 | I29: =LOOKUP(1,0/(($D$3=数据提取表!$A:$A)*($A29=数据提取表!$B:$B)),数据提取表!J:J) -> 12.6286 | J29: =LOOKUP(1,0/(($D$3=数据提取表!$A:$A)*($A29=数据提取表!$B:$B)),数据提取表!K:K) -> 0.9302 | K29: =J29/G29 -> 0.067449786 | L29: =LOOKUP(1,0/(($D$3=数据提取表!$A:$A)*($A29=数据提取表!$B:$B)),数据提取表!M:M) -> 27.29 | M29: =计划电量!O24 -> 323 | N29: =L29-M29/31*日报辅助图!$D$1 -> 6.4512903 | O29: =L29/M29 -> 0.084489164 | P29: =N29/M29 -> 0.019973035 | Q29: =L29+AG29+AH29 -> 303.3231 | R29: =计划电量!H24 -> 959 | S29: =Q29-(计划电量!N24+计划电量!O24/31*日报辅助图!$D$1) -> -29.51561 | T29: =Q29/R29 -> 0.31629103 | U29: =S29/R29 -> -0.030777487 | V29: {=LOOKUP(1,0/(($D$3=数据提取表!$A:$A)*($A29=数据提取表!$B:$B)),数据提取表!R:R)} -> 1111.2825 | W29: =计划电量!F24 -> 3541 | X29: =V29-(计划电量!G24+计划电量!N24+计划电量!O24/31*日报辅助图!$D$1) -> -66.55621 | Y29: =V29/W29 -> 0.31383296 | Z29: =X29/W29 -> -0.01879588 | AA29: {=LOOKUP(1,0/(($D$3=数据提取表!$A:$A)*($A29=数据提取表!$B:$B)),数据提取表!AC:AC)} -> 0 | AB29: {=LOOKUP(1,0/(($D$3=数据提取表!$A:$A)*($A29=数据提取表!$B:$B)),数据提取表!AD:AD)} -> 0 | AG29: 276.0331
A30: 光羿青阳光伏电站 | B30: BO22 | C30: 石拐光羿青阳 | D30: 100 | E30: =LOOKUP(1,0/(($D$3=数据提取表!$A:$A)*($A30=数据提取表!$B:$B)),数据提取表!E:E) -> 晴 | F30: =LOOKUP(1,0/(($D$3=数据提取表!$A:$A)*($A30=数据提取表!$B:$B)),数据提取表!F:F) -> 7.71 | G30: =LOOKUP(1,0/(($D$3=数据提取表!$A:$A)*($A30=数据提取表!$B:$B)),数据提取表!H:H) -> 58.122 | H30: =LOOKUP(1,0/(($D$3=数据提取表!$A:$A)*($A30=数据提取表!$B:$B)),数据提取表!I:I) -> 52.2362 | I30: =LOOKUP(1,0/(($D$3=数据提取表!$A:$A)*($A30=数据提取表!$B:$B)),数据提取表!J:J) -> 49.924 | J30: =LOOKUP(1,0/(($D$3=数据提取表!$A:$A)*($A30=数据提取表!$B:$B)),数据提取表!K:K) -> 5.8416 | K30: =J30/G30 -> 0.10050583 | L30: =LOOKUP(1,0/(($D$3=数据提取表!$A:$A)*($A30=数据提取表!$B:$B)),数据提取表!M:M) -> 110.7 | M30: =计划电量!O25 -> 1575 | N30: =L30-M30/31*日报辅助图!$D$1 -> 9.0870968 | O30: =L30/M30 -> 0.070285714 | P30: =N30/M30 -> 0.0057695853 | Q30: =L30+AG30+AH30 -> 1392.563 | R30: =计划电量!H25 -> 4518 | S30: =Q30-(计划电量!N25+计划电量!O25/31*日报辅助图!$D$1) -> -97.049903 | T30: =Q30/R30 -> 0.30822554 | U30: =S30/R30 -> -0.021480722 | V30: {=LOOKUP(1,0/(($D$3=数据提取表!$A:$A)*($A30=数据提取表!$B:$B)),数据提取表!R:R)} -> 4631.556 | W30: =计划电量!F25 -> 15895 | X30: =V30-(计划电量!G25+计划电量!N25+计划电量!O25/31*日报辅助图!$D$1) -> -658.0569 | Y30: =V30/W30 -> 0.29138446 | Z30: =X30/W30 -> -0.041400246 | AA30: {=LOOKUP(1,0/(($D$3=数据提取表!$A:$A)*($A30=数据提取表!$B:$B)),数据提取表!AC:AC)} -> 0 | AB30: {=LOOKUP(1,0/(($D$3=数据提取表!$A:$A)*($A30=数据提取表!$B:$B)),数据提取表!AD:AD)} -> 0 | AG30: 1281.863
A31: 奈曼旗汇特光伏电站 | B31: BO23 | C31: 奈曼旗汇特 | D31: 30 | E31: =LOOKUP(1,0/(($D$3=数据提取表!$A:$A)*($A31=数据提取表!$B:$B)),数据提取表!E:E) -> 晴 | F31: =LOOKUP(1,0/(($D$3=数据提取表!$A:$A)*($A31=数据提取表!$B:$B)),数据提取表!F:F) -> 7.84 | G31: =LOOKUP(1,0/(($D$3=数据提取表!$A:$A)*($A31=数据提取表!$B:$B)),数据提取表!H:H) -> 19.2399 | H31: =LOOKUP(1,0/(($D$3=数据提取表!$A:$A)*($A31=数据提取表!$B:$B)),数据提取表!I:I) -> 19.2399 | I31: =LOOKUP(1,0/(($D$3=数据提取表!$A:$A)*($A31=数据提取表!$B:$B)),数据提取表!J:J) -> 19.008 | J31: =LOOKUP(1,0/(($D$3=数据提取表!$A:$A)*($A31=数据提取表!$B:$B)),数据提取表!K:K) -> 0 | K31: =J31/G31 -> 0 | L31: =LOOKUP(1,0/(($D$3=数据提取表!$A:$A)*($A31=数据提取表!$B:$B)),数据提取表!M:M) -> 32.0496 | M31: =计划电量!O26 -> 468 | N31: =L31-M31/31*日报辅助图!$D$1 -> 1.8560516 | O31: =L31/M31 -> 0.068482051 | P31: =N31/M31 -> 0.0039659222 | Q31: =L31+AG31+AH31 -> 459.096 | R31: =计划电量!H26 -> 1279 | S31: =Q31-(计划电量!N26+计划电量!O26/31*日报辅助图!$D$1) -> 27.902452 | T31: =Q31/R31 -> 0.35894918 | U31: =S31/R31 -> 0.021815834 | V31: {=LOOKUP(1,0/(($D$3=数据提取表!$A:$A)*($A31=数据提取表!$B:$B)),数据提取表!R:R)} -> 1636.8528 | W31: =计划电量!F26 -> 4805 | X31: =V31-(计划电量!G26+计划电量!N26+计划电量!O26/31*日报辅助图!$D$1) -> -36.340748 | Y31: =V31/W31 -> 0.34065615 | Z31: =X31/W31 -> -0.007563111 | AA31: {=LOOKUP(1,0/(($D$3=数据提取表!$A:$A)*($A31=数据提取表!$B:$B)),数据提取表!AC:AC)} -> 0 | AB31: {=LOOKUP(1,0/(($D$3=数据提取表!$A:$A)*($A31=数据提取表!$B:$B)),数据提取表!AD:AD)} -> 0 | AG31: 427.0464
A32: 特电乌宁巴风电一场 | B32: BO24 | C32: 特电乌宁巴 | D32: 250 | E32: =LOOKUP(1,0/(($D$3=数据提取表!$A:$A)*($A32=数据提取表!$B:$B)),数据提取表!E:E) -> 晴 | F32: {=LOOKUP(1,0/(($D$3=数据提取表!$A:$A)*($A32=数据提取表!$B:$B)),数据提取表!G:G)} -> 6.17 | G32: =LOOKUP(1,0/(($D$3=数据提取表!$A:$A)*($A32=数据提取表!$B:$B)),数据提取表!H:H) -> 165.4552 | H32: =LOOKUP(1,0/(($D$3=数据提取表!$A:$A)*($A32=数据提取表!$B:$B)),数据提取表!I:I) -> 129.7204 | I32: =LOOKUP(1,0/(($D$3=数据提取表!$A:$A)*($A32=数据提取表!$B:$B)),数据提取表!J:J) -> 125.4 | J32: =LOOKUP(1,0/(($D$3=数据提取表!$A:$A)*($A32=数据提取表!$B:$B)),数据提取表!K:K) -> 35.7348 | K32: =J32/G32 -> 0.21597871 | L32: =LOOKUP(1,0/(($D$3=数据提取表!$A:$A)*($A32=数据提取表!$B:$B)),数据提取表!M:M) -> 277.2 | M32: =计划电量!O27 -> 5197 | N32: =L32-M32/31*日报辅助图!$D$1 -> -58.090323 | O32: =L32/M32 -> 0.053338464 | P32: =N32/M32 -> -0.011177665 | Q32: =L32+AG32+AH32 -> 5899.08 | R32: =计划电量!H27 -> 16303 | S32: =Q32-(计划电量!N27+计划电量!O27/31*日报辅助图!$D$1) -> -1186.2103 | T32: =Q32/R32 -> 0.36184015 | U32: =S32/R32 -> -0.072760248 | V32: {=LOOKUP(1,0/(($D$3=数据提取表!$A:$A)*($A32=数据提取表!$B:$B)),数据提取表!R:R)} -> 20434.92 | W32: =计划电量!F27 -> 61425 | X32: =V32-(计划电量!G27+计划电量!N27+计划电量!O27/31*日报辅助图!$D$1) -> -3708.3703 | Y32: =V32/W32 -> 0.33268083 | Z32: =X32/W32 -> -0.060372329 | AA32: {=LOOKUP(1,0/(($D$3=数据提取表!$A:$A)*($A32=数据提取表!$B:$B)),数据提取表!AC:AC)} -> 0 | AB32: {=LOOKUP(1,0/(($D$3=数据提取表!$A:$A)*($A32=数据提取表!$B:$B)),数据提取表!AD:AD)} -> 0 | AG32: 5621.88
A33: 风盛古日班风电一场 | B33: BO25 | C33: 风盛古日班 | D33: 335 | E33: =LOOKUP(1,0/(($D$3=数据提取表!$A:$A)*($A33=数据提取表!$B:$B)),数据提取表!E:E) -> 晴 | F33: {=LOOKUP(1,0/(($D$3=数据提取表!$A:$A)*($A33=数据提取表!$B:$B)),数据提取表!G:G)} -> 7.69 | G33: =LOOKUP(1,0/(($D$3=数据提取表!$A:$A)*($A33=数据提取表!$B:$B)),数据提取表!H:H) -> 308.3898 | H33: =LOOKUP(1,0/(($D$3=数据提取表!$A:$A)*($A33=数据提取表!$B:$B)),数据提取表!I:I) -> 149.7069 | I33: =LOOKUP(1,0/(($D$3=数据提取表!$A:$A)*($A33=数据提取表!$B:$B)),数据提取表!J:J) -> 145.64 | J33: =LOOKUP(1,0/(($D$3=数据提取表!$A:$A)*($A33=数据提取表!$B:$B)),数据提取表!K:K) -> 158.6829 | K33: =J33/G33 -> 0.51455301 | L33: =LOOKUP(1,0/(($D$3=数据提取表!$A:$A)*($A33=数据提取表!$B:$B)),数据提取表!M:M) -> 418.88 | M33: =计划电量!O28 -> 6720 | N33: =L33-M33/31*日报辅助图!$D$1 -> -14.668387 | O33: =L33/M33 -> 0.062333333 | P33: =N33/M33 -> -0.0021827957 | Q33: =L33+AG33+AH33 -> 8425.56 | R33: =计划电量!H28 -> 21878 | S33: =Q33-(计划电量!N28+计划电量!O28/31*日报辅助图!$D$1) -> -1303.9884 | T33: =Q33/R33 -> 0.38511564 | U33: =S33/R33 -> -0.059602724 | V33: {=LOOKUP(1,0/(($D$3=数据提取表!$A:$A)*($A33=数据提取表!$B:$B)),数据提取表!R:R)} -> 32351 | W33: =计划电量!F28 -> 83580 | X33: =V33-(计划电量!G28+计划电量!N28+计划电量!O28/31*日报辅助图!$D$1) -> 1059.4516 | Y33: =V33/W33 -> 0.38706628 | Z33: =X33/W33 -> 0.012675899 | AA33: {=LOOKUP(1,0/(($D$3=数据提取表!$A:$A)*($A33=数据提取表!$B:$B)),数据提取表!AC:AC)} -> 0 | AB33: {=LOOKUP(1,0/(($D$3=数据提取表!$A:$A)*($A33=数据提取表!$B:$B)),数据提取表!AD:AD)} -> 0 | AG33: 8006.68
A34: 新园古日班风电一场 | B34: BO26 | C34: 新园古日班 | D34: 250 | E34: =LOOKUP(1,0/(($D$3=数据提取表!$A:$A)*($A34=数据提取表!$B:$B)),数据提取表!E:E) -> 晴 | F34: {=LOOKUP(1,0/(($D$3=数据提取表!$A:$A)*($A34=数据提取表!$B:$B)),数据提取表!G:G)} -> 7.5 | G34: =LOOKUP(1,0/(($D$3=数据提取表!$A:$A)*($A34=数据提取表!$B:$B)),数据提取表!H:H) -> 195.3072 | H34: =LOOKUP(1,0/(($D$3=数据提取表!$A:$A)*($A34=数据提取表!$B:$B)),数据提取表!I:I) -> 140.085 | I34: =LOOKUP(1,0/(($D$3=数据提取表!$A:$A)*($A34=数据提取表!$B:$B)),数据提取表!J:J) -> 135.96 | J34: =LOOKUP(1,0/(($D$3=数据提取表!$A:$A)*($A34=数据提取表!$B:$B)),数据提取表!K:K) -> 55.2222 | K34: =J34/G34 -> 0.28274534 | L34: =LOOKUP(1,0/(($D$3=数据提取表!$A:$A)*($A34=数据提取表!$B:$B)),数据提取表!M:M) -> 337.92 | M34: =计划电量!O29 -> 4629 | N34: =L34-M34/31*日报辅助图!$D$1 -> 39.274839 | O34: =L34/M34 -> 0.073000648 | P34: =N34/M34 -> 0.0084845191 | Q34: =L34+AG34+AH34 -> 6279.24 | R34: =计划电量!H29 -> 15988 | S34: =Q34-(计划电量!N29+计划电量!O29/31*日报辅助图!$D$1) -> -1014.4052 | T34: =Q34/R34 -> 0.39274706 | U34: =S34/R34 -> -0.063447909 | V34: {=LOOKUP(1,0/(($D$3=数据提取表!$A:$A)*($A34=数据提取表!$B:$B)),数据提取表!R:R)} -> 22826.76 | W34: =计划电量!F29 -> 61280 | X34: =V34-(计划电量!G29+计划电量!N29+计划电量!O29/31*日报辅助图!$D$1) -> -846.88516 | Y34: =V34/W34 -> 0.37249935 | Z34: =X34/W34 -> -0.013819928 | AA34: {=LOOKUP(1,0/(($D$3=数据提取表!$A:$A)*($A34=数据提取表!$B:$B)),数据提取表!AC:AC)} -> 0 | AB34: {=LOOKUP(1,0/(($D$3=数据提取表!$A:$A)*($A34=数据提取表!$B:$B)),数据提取表!AD:AD)} -> 0 | AG34: 5941.32
A35: 新隆砬子山风电 | B35: BO27 | C35: 丰宁砬子山 | D35: 60 | E35: =LOOKUP(1,0/(($D$3=数据提取表!$A:$A)*($A35=数据提取表!$B:$B)),数据提取表!E:E) -> 晴 | F35: {=LOOKUP(1,0/(($D$3=数据提取表!$A:$A)*($A35=数据提取表!$B:$B)),数据提取表!G:G)} -> 4.17 | G35: =LOOKUP(1,0/(($D$3=数据提取表!$A:$A)*($A35=数据提取表!$B:$B)),数据提取表!H:H) -> 28.7016 | H35: =LOOKUP(1,0/(($D$3=数据提取表!$A:$A)*($A35=数据提取表!$B:$B)),数据提取表!I:I) -> 28.7016 | I35: =LOOKUP(1,0/(($D$3=数据提取表!$A:$A)*($A35=数据提取表!$B:$B)),数据提取表!J:J) -> 28.14 | J35: =LOOKUP(1,0/(($D$3=数据提取表!$A:$A)*($A35=数据提取表!$B:$B)),数据提取表!K:K) -> 0 | K35: =J35/G35 -> 0 | L35: =LOOKUP(1,0/(($D$3=数据提取表!$A:$A)*($A35=数据提取表!$B:$B)),数据提取表!M:M) -> 80.85 | M35: =计划电量!O30 -> 1011 | N35: =L35-M35/31*日报辅助图!$D$1 -> 15.624194 | O35: =L35/M35 -> 0.079970326 | P35: =N35/M35 -> 0.015454197 | Q35: =L35+AG35+AH35 -> 1379.7 | R35: =计划电量!H30 -> 3329 | S35: =Q35-(计划电量!N30+计划电量!O30/31*日报辅助图!$D$1) -> -74.525806 | T35: =Q35/R35 -> 0.41444878 | U35: =S35/R35 -> -0.022386845 | V35: {=LOOKUP(1,0/(($D$3=数据提取表!$A:$A)*($A35=数据提取表!$B:$B)),数据提取表!R:R)} -> 5431.23 | W35: =计划电量!F30 -> 14049 | X35: =V35-(计划电量!G30+计划电量!N30+计划电量!O30/31*日报辅助图!$D$1) -> 45.004194 | Y35: =V35/W35 -> 0.38659193 | Z35: =X35/W35 -> 0.0032033734 | AA35: {=LOOKUP(1,0/(($D$3=数据提取表!$A:$A)*($A35=数据提取表!$B:$B)),数据提取表!AC:AC)} -> 0 | AB35: {=LOOKUP(1,0/(($D$3=数据提取表!$A:$A)*($A35=数据提取表!$B:$B)),数据提取表!AD:AD)} -> 0 | AG35: 1298.85
A36: 福合风电场 | B36: BO28 | C36: 西丰福合 | D36: 100 | E36: =LOOKUP(1,0/(($D$3=数据提取表!$A:$A)*($A36=数据提取表!$B:$B)),数据提取表!E:E) -> 晴 | F36: {=LOOKUP(1,0/(($D$3=数据提取表!$A:$A)*($A36=数据提取表!$B:$B)),数据提取表!G:G)} -> 8.46 | G36: =LOOKUP(1,0/(($D$3=数据提取表!$A:$A)*($A36=数据提取表!$B:$B)),数据提取表!H:H) -> 177.4575 | H36: =LOOKUP(1,0/(($D$3=数据提取表!$A:$A)*($A36=数据提取表!$B:$B)),数据提取表!I:I) -> 131.3592 | I36: =LOOKUP(1,0/(($D$3=数据提取表!$A:$A)*($A36=数据提取表!$B:$B)),数据提取表!J:J) -> 129.228 | J36: =LOOKUP(1,0/(($D$3=数据提取表!$A:$A)*($A36=数据提取表!$B:$B)),数据提取表!K:K) -> 46.0983 | K36: =J36/G36 -> 0.25977093 | L36: =LOOKUP(1,0/(($D$3=数据提取表!$A:$A)*($A36=数据提取表!$B:$B)),数据提取表!M:M) -> 212.256 | M36: =计划电量!O31 -> 2214 | N36: =L36-M36/31*日报辅助图!$D$1 -> 69.41729 | O36: =L36/M36 -> 0.095869919 | P36: =N36/M36 -> 0.03135379 | Q36: =L36+AG36+AH36 -> 2569.512 | R36: =计划电量!H31 -> 7073 | S36: =Q36-(计划电量!N31+计划电量!O31/31*日报辅助图!$D$1) -> -536.32671 | T36: =Q36/R36 -> 0.3632846 | U36: =S36/R36 -> -0.075827331 | V36: {=LOOKUP(1,0/(($D$3=数据提取表!$A:$A)*($A36=数据提取表!$B:$B)),数据提取表!R:R)} -> 9548.616 | W36: =计划电量!F31 -> 25315 | X36: =V36-(计划电量!G31+计划电量!N31+计划电量!O31/31*日报辅助图!$D$1) -> -120.22271 | Y36: =V36/W36 -> 0.37719202 | Z36: =X36/W36 -> -0.0047490701 | AA36: {=LOOKUP(1,0/(($D$3=数据提取表!$A:$A)*($A36=数据提取表!$B:$B)),数据提取表!AC:AC)} -> 0 | AB36: {=LOOKUP(1,0/(($D$3=数据提取表!$A:$A)*($A36=数据提取表!$B:$B)),数据提取表!AD:AD)} -> 0 | AG36: 2357.256
A37: 光炽将军尧储能电站 | B37: BO29 | C37: 土右光炽将军尧 | D37: 378 | E37: =LOOKUP(1,0/(($D$3=数据提取表!$A:$A)*($A37=数据提取表!$B:$B)),数据提取表!E:E) -> 晴 | F37: =LOOKUP(1,0/(($D$3=数据提取表!$A:$A)*($A37=数据提取表!$B:$B)),数据提取表!F:F) -> 6.56 | G37: =LOOKUP(1,0/(($D$3=数据提取表!$A:$A)*($A37=数据提取表!$B:$B)),数据提取表!H:H) -> 227.1155 | H37: =LOOKUP(1,0/(($D$3=数据提取表!$A:$A)*($A37=数据提取表!$B:$B)),数据提取表!I:I) -> 208.8366 | I37: =LOOKUP(1,0/(($D$3=数据提取表!$A:$A)*($A37=数据提取表!$B:$B)),数据提取表!J:J) -> 206.382 | J37: =LOOKUP(1,0/(($D$3=数据提取表!$A:$A)*($A37=数据提取表!$B:$B)),数据提取表!K:K) -> 17.1153 | K37: =J37/G37 -> 0.075359454 | L37: =LOOKUP(1,0/(($D$3=数据提取表!$A:$A)*($A37=数据提取表!$B:$B)),数据提取表!M:M) -> 451.902 | M37: =计划电量!O32 -> 4972 | N37: =L37-M37/31*日报辅助图!$D$1 -> 131.12781 | O37: =L37/M37 -> 0.090889381 | P37: =N37/M37 -> 0.026373251 | Q37: =L37+AG37+AH37 -> 5550.435 | R37: =计划电量!H32 -> 14920 | S37: =Q37-(计划电量!N32+计划电量!O32/31*日报辅助图!$D$1) -> 492.66081 | T37: =Q37/R37 -> 0.37201307 | U37: =S37/R37 -> 0.033020161 | V37: {=LOOKUP(1,0/(($D$3=数据提取表!$A:$A)*($A37=数据提取表!$B:$B)),数据提取表!R:R)} -> 18582.466 | W37: =计划电量!F32 -> 57321 | X37: =V37-(计划电量!G32+计划电量!N32+计划电量!O32/31*日报辅助图!$D$1) -> 878.69181 | Y37: =V37/W37 -> 0.32418252 | Z37: =X37/W37 -> 0.015329317 | AA37: {=LOOKUP(1,0/(($D$3=数据提取表!$A:$A)*($A37=数据提取表!$B:$B)),数据提取表!AC:AC)} -> 0 | AB37: {=LOOKUP(1,0/(($D$3=数据提取表!$A:$A)*($A37=数据提取表!$B:$B)),数据提取表!AD:AD)} -> 0 | AG37: 5098.533
B38: 存量项目小计 | D38: =SUM(D28:D37) -> 1623 | E38: / | F38: / | G38: =SUM(G28:G37) -> 1320.8522 | H38: =SUM(H28:H37) -> 980.7002 | I38: =SUM(I28:I37) -> 958.182 | J38: =SUM(J28:J37) -> 338.9442 | K38: =J38/G38 -> 0.25661024 | L38: =SUM(L28:L37) -> 2114.2576 | M38: =SUM(M28:M37) -> 30019 | N38: =SUM(N28:N37) -> 177.54792 | O38: =L38/M38 -> 0.070430647 | P38: =N38/M38 -> 0.0059145182 | Q38: =SUM(Q28:Q37) -> 34984.734 | R38: =SUM(R28:R37) -> 94347 | S38: =SUM(S28:S37) -> -3908.9758 | T38: =Q38/R38 -> 0.37080918 | U38: =S38/R38 -> -0.041431903 | V38: =SUM(V28:V37) -> 125639.7 | W38: =SUM(W28:W37) -> 356071 | X38: =SUM(X28:X37) -> -4382.0117 | Y38: =V38/W38 -> 0.35285013 | Z38: =X38/W38 -> -0.012306567 | AA38: =SUM(AA28:AA37) -> 0 | AB38: =SUM(AB28:AB37) -> 0 | AG38: 32870.476
A39: 天津武清白古屯风电场 | B39: BO30 | C39: 武清白古屯 | D39: 33 | E39: =LOOKUP(1,0/(($D$3=数据提取表!$A:$A)*($A39=数据提取表!$B:$B)),数据提取表!E:E) -> 晴 | F39: {=LOOKUP(1,0/(($D$3=数据提取表!$A:$A)*($A39=数据提取表!$B:$B)),数据提取表!G:G)} -> 6.55 | G39: =LOOKUP(1,0/(($D$3=数据提取表!$A:$A)*($A39=数据提取表!$B:$B)),数据提取表!H:H) -> 41.4181 | H39: =LOOKUP(1,0/(($D$3=数据提取表!$A:$A)*($A39=数据提取表!$B:$B)),数据提取表!I:I) -> 41.1979 | I39: =LOOKUP(1,0/(($D$3=数据提取表!$A:$A)*($A39=数据提取表!$B:$B)),数据提取表!J:J) -> 40.26 | J39: =LOOKUP(1,0/(($D$3=数据提取表!$A:$A)*($A39=数据提取表!$B:$B)),数据提取表!K:K) -> 0 | K39: =J39/G39 -> 0 | L39: {=LOOKUP(1,0/(($D$3=数据提取表!$A:$A)*($A39=数据提取表!$B:$B)),数据提取表!M:M)} -> 76.56 | M39: =计划电量!O33 -> 1121 | N39: =L39-M39/31*日报辅助图!$D$1 -> 4.2374194 | O39: =L39/M39 -> 0.068296164 | P39: =N39/M39 -> 0.0037800351 | Q39: =L39+AG39+AH39 -> 698.22 | R39: =计划电量!H33 -> 2850 | S39: =Q39-(计划电量!N33+计划电量!O33/31*日报辅助图!$D$1) -> -460.10258 | T39: =Q39/R39 -> 0.24498947 | U39: =S39/R39 -> -0.1614395 | V39: {=LOOKUP(1,0/(($D$3=数据提取表!$A:$A)*($A39=数据提取表!$B:$B)),数据提取表!R:R)} -> 2345.64 | W39: =计划电量!F33 -> 7604 | X39: =V39-(计划电量!G33+计划电量!N33+计划电量!O33/31*日报辅助图!$D$1) -> -319.68258 | Y39: =V39/W39 -> 0.30847449 | Z39: =X39/W39 -> -0.04204137 | AA39: {=LOOKUP(1,0/(($D$3=数据提取表!$A:$A)*($A39=数据提取表!$B:$B)),数据提取表!AC:AC)} -> 0 | AB39: {=LOOKUP(1,0/(($D$3=数据提取表!$A:$A)*($A39=数据提取表!$B:$B)),数据提取表!AD:AD)} -> 0 | AG39: 621.66
B40: BO31 | C40: 武清二期 | D40: 48 | E40: =LOOKUP(1,0/(($D$3=数据提取表!$A:$A)*($A40=数据提取表!$B:$B)),数据提取表!E:E) -> #N/A | F40: =LOOKUP(1,0/(($D$3=数据提取表!$A:$A)*($A40=数据提取表!$B:$B)),数据提取表!F:F) -> #N/A | G40: =LOOKUP(1,0/(($D$3=数据提取表!$A:$A)*($A40=数据提取表!$B:$B)),数据提取表!H:H) -> #N/A | H40: =LOOKUP(1,0/(($D$3=数据提取表!$A:$A)*($A40=数据提取表!$B:$B)),数据提取表!I:I) -> #N/A | I40: =LOOKUP(1,0/(($D$3=数据提取表!$A:$A)*($A40=数据提取表!$B:$B)),数据提取表!J:J) -> #N/A | J40: =LOOKUP(1,0/(($D$3=数据提取表!$A:$A)*($A40=数据提取表!$B:$B)),数据提取表!K:K) -> #N/A | K40: =J40/G40 -> #N/A | L40: =LOOKUP(1,0/(($D$3=数据提取表!$A:$A)*($A40=数据提取表!$B:$B)),数据提取表!M:M) -> #N/A | M40: 0 | N40: =L40-M40/31*日报辅助图!$D$1 -> #N/A | O40: =L40/M40 -> #N/A | P40: =N40/M40 -> #N/A | Q40: =L40 -> #N/A | R40: 0 | S40: =Q40-(计划电量!K34/31*日报辅助图!$D$1) -> #N/A | T40: =Q40/R40 -> #N/A | U40: =S40/R40 -> #N/A | V40: {=LOOKUP(1,0/(($D$3=数据提取表!$A:$A)*($A40=数据提取表!$B:$B)),数据提取表!R:R)} -> #N/A | W40: 2912 | X40: =V40-(计划电量!K34/31*日报辅助图!$D$1) -> #N/A | Y40: =V40/W40 -> #N/A | Z40: =X40/W40 -> #N/A | AA40: {=LOOKUP(1,0/(($D$3=数据提取表!$A:$A)*($A40=数据提取表!$B:$B)),数据提取表!AC:AC)} -> #N/A | AB40: {=LOOKUP(1,0/(($D$3=数据提取表!$A:$A)*($A40=数据提取表!$B:$B)),数据提取表!AD:AD)} -> #N/A | AG40: #N/A
B41: BO32 | C41: 新隆光伏 | D41: 100 | E41: =LOOKUP(1,0/(($D$3=数据提取表!$A:$A)*($A41=数据提取表!$B:$B)),数据提取表!E:E) -> #N/A | F41: =LOOKUP(1,0/(($D$3=数据提取表!$A:$A)*($A41=数据提取表!$B:$B)),数据提取表!F:F) -> #N/A | G41: =LOOKUP(1,0/(($D$3=数据提取表!$A:$A)*($A41=数据提取表!$B:$B)),数据提取表!H:H) -> #N/A | H41: =LOOKUP(1,0/(($D$3=数据提取表!$A:$A)*($A41=数据提取表!$B:$B)),数据提取表!I:I) -> #N/A | I41: =LOOKUP(1,0/(($D$3=数据提取表!$A:$A)*($A41=数据提取表!$B:$B)),数据提取表!J:J) -> #N/A | J41: =LOOKUP(1,0/(($D$3=数据提取表!$A:$A)*($A41=数据提取表!$B:$B)),数据提取表!K:K) -> #N/A | K41: =J41/G41 -> #N/A | L41: =LOOKUP(1,0/(($D$3=数据提取表!$A:$A)*($A41=数据提取表!$B:$B)),数据提取表!M:M) -> #N/A | M41: 0 | N41: =L41-M41/31*日报辅助图!$D$1 -> #N/A | O41: =L41/M41 -> #N/A | P41: =N41/M41 -> #N/A | Q41: =L41 -> #N/A | R41: 0 | S41: =Q41-(计划电量!K35/31*日报辅助图!$D$1) -> #N/A | T41: =Q41/R41 -> #N/A | U41: =S41/R41 -> #N/A | V41: {=LOOKUP(1,0/(($D$3=数据提取表!$A:$A)*($A41=数据提取表!$B:$B)),数据提取表!R:R)} -> #N/A | W41: 4555 | X41: =V41-(计划电量!K35/31*日报辅助图!$D$1) -> #N/A | Y41: =V41/W41 -> #N/A | Z41: =X41/W41 -> #N/A | AA41: {=LOOKUP(1,0/(($D$3=数据提取表!$A:$A)*($A41=数据提取表!$B:$B)),数据提取表!AC:AC)} -> #N/A | AB41: {=LOOKUP(1,0/(($D$3=数据提取表!$A:$A)*($A41=数据提取表!$B:$B)),数据提取表!AD:AD)} -> #N/A | AG41: #N/A
B42: BO33 | C42: 上谷光伏 | D42: 200 | E42: =LOOKUP(1,0/(($D$3=数据提取表!$A:$A)*($A42=数据提取表!$B:$B)),数据提取表!E:E) -> #N/A | F42: =LOOKUP(1,0/(($D$3=数据提取表!$A:$A)*($A42=数据提取表!$B:$B)),数据提取表!F:F) -> #N/A | G42: =LOOKUP(1,0/(($D$3=数据提取表!$A:$A)*($A42=数据提取表!$B:$B)),数据提取表!H:H) -> #N/A | H42: =LOOKUP(1,0/(($D$3=数据提取表!$A:$A)*($A42=数据提取表!$B:$B)),数据提取表!I:I) -> #N/A | I42: =LOOKUP(1,0/(($D$3=数据提取表!$A:$A)*($A42=数据提取表!$B:$B)),数据提取表!J:J) -> #N/A | J42: =LOOKUP(1,0/(($D$3=数据提取表!$A:$A)*($A42=数据提取表!$B:$B)),数据提取表!K:K) -> #N/A | K42: =J42/G42 -> #N/A | L42: =LOOKUP(1,0/(($D$3=数据提取表!$A:$A)*($A42=数据提取表!$B:$B)),数据提取表!M:M) -> #N/A | M42: 0 | N42: =L42-M42/31*日报辅助图!$D$1 -> #N/A | O42: =L42/M42 -> #N/A | P42: =N42/M42 -> #N/A | Q42: =L42 -> #N/A | R42: 0 | S42: =Q42-(计划电量!K36/31*日报辅助图!$D$1) -> #N/A | T42: =Q42/R42 -> #N/A | U42: =S42/R42 -> #N/A | V42: {=LOOKUP(1,0/(($D$3=数据提取表!$A:$A)*($A42=数据提取表!$B:$B)),数据提取表!R:R)} -> #N/A | W42: 7411 | X42: =V42-(计划电量!K36/31*日报辅助图!$D$1) -> #N/A | Y42: =V42/W42 -> #N/A | Z42: =X42/W42 -> #N/A | AA42: {=LOOKUP(1,0/(($D$3=数据提取表!$A:$A)*($A42=数据提取表!$B:$B)),数据提取表!AC:AC)} -> #N/A | AB42: {=LOOKUP(1,0/(($D$3=数据提取表!$A:$A)*($A42=数据提取表!$B:$B)),数据提取表!AD:AD)} -> #N/A | AG42: #N/A
...

Sheet 自由分析表
B1: 起始日期 | D1: 45413 | G1: 结束日期 | H1: 45414 | J1: =H1-D1+1 -> 2 | K1: 天 | L1: 4月 | M1: 30 | N1: 起始月份 | O1: =MONTH(D1) -> 5 | P1: 结束月份 | Q1: =MONTH(H1) -> 5 | R1: 月数 | S1: =Q1-O1+1 -> 1
B2: 序号 | C2: 电站名称 | D2: 计划并网容量（MW） | E2: =O1&"至"&Q1&"月计划电量" -> 5至5月计划电量 | F2: 辐照量（kWh/m2）/风速（m/s） | G2: 理论发电量（万kWh） | H2: 实际发电量（万kWh） | I2: 上网电量（万kWh） | J2: 年度计划电量 | K2: =O1&"至"&Q1&"月电量完成率" -> 5至5月电量完成率 | L2: 年度电量完成率 | M2: 与计划偏差电量 | N2: 限电量（万kWh） | O2: 限电率（%） | P2: 检修损失（机组检修+输变电检修） | Q2: 故障损失电量（机组故障+输变电故障） | R2: 发电设备检修损失 | S2: 发电设备故障损失 | T2: 输变电故障损失电量（万kWh | U2: 输变电检修损失电量（万kWh） | V2: 受累损失 | W2: 电网故障损失电量（万kWh） | X2: 自然灾害损失电量（万kWh） | Y2: 其他受累损失电量（万kWh） | Z2: 工程期损失电量（万kWh） | AA2: 设备可利用率（日%） | AB2: 故障损失率 | AC2: 24年故障损失率基线值 | AD2: 检修损失率 | AE2: 24年检修损失率基线值 | AF2: 非限电损失率
